Workbook

Sheet 개념
A1: Bricolage: analysis and refactoring - 삶의 비용과 효과를 재구성하는 방법
A2: bricoleur: 도구를 닥치는 대로 조합해 만드는 예술가 | D2: ‘브리콜레르(bricoleur)’는 레비스트로스의 『야생의 사고』에서 유래한 개념으로, 주어진 재료와 도구를 자유롭게 조합해 문제를 해결하는 ‘손재주꾼’ 또는 ‘현장형 실천형 지식인’을 뜻합니다. 아트앤스터디 +1 이 개념은 엔지니어링(설계·계획 중심)과 대비되며, 제한된 자원 속에서 즉흥적으로 창의적 해결책을 만드는 방식으로 설명됩니다.
A3: 요약 | B3: 적절한 제품을 구매하라
B4: 스스로 만들어라
B5: 노동하지말고, 설정만 비틀어서 5분이내 구현하라
A7: - 소모품은 물리적으로 소모되는 물질 (필터, 건전지, 세제 등) — 정기적으로 보충해야 하는 것
A8: - 병원비는 서비스 지출이자 유지보수 실패의 downstream 비용 — OPEX에 해당
A9: - 연간 몇회 구입하는 건은 시간을 1/12로 하고, 양을 N으로 한다. 그렇게 해야 계산이 간단하고, 직관적으로 식을 이해할 수 있다. 모두 수정
G11: =G12/F12 -> 0.31578947
F12: =COUNTA(F14:F70) -> 57 | G12: =COUNTA(G14:G70) -> 18
A13: 구분 | B13: 방법 | C13: 포인트 | D13: 사례 | E13: 분야 | F13: 원가절감 | G13: 가치제고 | H13: 개선 효과 | I13: 일반인 | J13: 일반인_활동 | K13: Bricoleur | L13: Bricoleur_활동 | P13: 일반인 (The Consumer) | Q13: Bricoleur (The Architect)
A14: 비용 절감 | B14: 1타 N피 | C14: 한 제품의 특징을 여러 분야에 적용 | D14: WD-40, 바세린, 니베아 크림 | E14: 생활 | F14: ○ | G14: ○ | H14: 내구성 개선 | I14: 15000 | J14: 용도별 전용 제품 복수 구매 | K14: 1500 | L14: 범용 제품 1개로 해결 | M14: =K14-I14 -> -13500 | P14: 목적별로 전용 하이엔드 제품을 각각 구매하여 공간과 비용을 낭비함. | Q14: 물질의 핵심 화학적·물리적 본질을 간파하여 하나의 자재로 일타십피함.
B15: positioning | C15: 저비용 position 확보 | D15: 중간에 낀 아파트 | E15: 주 | F15: ○ | I15: =300000*6/12 -> 150000 | J15: 외벽 한기 제거를 위한 가스 소비(동절기 6개월, 월 30만원) | K15: 0 | L15: 옆, 위, 아래 아파트의 온기 공유 | M15: =K15-I15 -> -150000 | P15: 브랜드와 대단지 프리미엄이라는 거품(10%)을 사기 위해 거대 영혼 가출 대출을 감사히 짊어짐. | Q15: 저비용 고효율 포지션을 명확히 장악하여 주거비의 고정 오버헤드를 물리적으로 컷(Cut)함.
B16: effectiveness | C16: 효과가 발생하는 부분에만 비용 투입 | D16: 온수매트 | E16: 주 | F16: ○ | I16: 150000 | J16: 안 쓰는 공간까지 보일러 풀가동 | K16: 30000 | L16: 동선 내 접촉 구역만 온수매트 타겟팅 | M16: =K16-I16 -> -120000 | P16: 보일러를 풀가동해 안 쓰는 방의 공기까지 데우며 가스비를 대기업에 덤핑함. | Q16: 내 피부와 신경계에 열이 닿는 실질적인 런타임 영역(온수매트)에만 비용을 집중 투입함.
B17: alternative | C17: 동일한 기능을 가지는 대체품 활용 | D17: 전열교환기 프레임에 스틸자 사용 | E17: 주 | F17: ○ | I17: 60000 | J17: 전용 정품 프레임 구입 및 교환(240만원/5년, 월 6만원) | K17: 5000 | L17: 스틸자 무한 재활용 | M17: =K17-I17 -> -55000
D18: 토마토로 과일 대체 | E18: 식 | F18: ○ | I18: 100000 | J18: 고가 제철/프리미엄 과일 | K18: 20000 | L18: 영양가 높은 토마토 통일 | M18: =K18-I18 -> -80000
D19: 모니터 거치대 대신 백과사전 | E19: 생활 | F19: ○ | I19: 20000 | J19: 브랜드 전용 거치대 구매 감가 | K19: 0 | L19: 기존 물성 활용 | M19: =K19-I19 -> -20000 | P19: 전용 모니터 거치대, 브랜드 소품을 카트에 담으며 포장재 쓰레기를 양산함. | Q19: 주위에 널린 고중량 물성(백과사전, 스틸자)을 팅커링(Tinkering)하여 기성품의 기능을 완벽히 대체함.
B20: DIY | C20: 고품질 제품 자작 | D20: 굵은 전선으로 고전류 오디오용 멀티탭 생산 | E20: 취미 | F20: ○ | G20: ○ | H20: spec 조절 가능 | I20: 0 | J20: 하이엔드 오디오 완제품 구매 감가 | K20: 10000 | L20: 부품 구매 후 자작 | M20: =K20-I20 -> 10000 | P20: 완제품에 붙은 브랜딩 마케팅 비용을 지불하며, 대기업 서비스(케어)의 노예가 됨. | Q20: 원재료 1%를 직접 소싱하고 빌드(Build)하여, 유통 마진을 파괴하고 최고 존엄의 럭셔리를 향유함.
D21: 게샤 원두를 사서 드립백 자작 | E21: 기호 | F21: ○ | G21: ○ | H21: 최상 기호품 향유 | I21: =5000*30 -> 150000 | J21: 브랜드 커피 전문점 사용(월 5000원 X 30회) | K21: =700*30 -> 21000 | L21: Top tier 생두/원두 소싱 후 직접 추출(700원 X 30회) | M21: =K21-I21 -> -129000
D22: 드립백을 사서 고급티백 자작 | E22: 기호 | F22: ○ | G22: ○ | H22: 최상 기호품 향유 | I22: =3000*10 -> 30000 | J22: 프리미엄 티 브랜드 완제품 구매(월 3000원 X10회) | K22: =50*30 -> 1500 | L22: 선물받은 차를 드립백으로 DIY | M22: =K22-I22 -> -28500
D23: LED 전구 + 한지로 조명만들기 | E23: 주 | F23: ○ | G23: ○ | H23: 고급스러운 분위기 | I23: =20000/20 -> 1000 | J23: 수입/디자이너 조명 구매 감가(20만원, 20개월 사용) | K23: =4000/20 -> 200 | L23: 부품 소싱 및 자작(전구 3천원, 프레임 천원) | M23: =K23-I23 -> -800
D24: 소니 모니터링 헤드폰 + 블루투스 리시버 | E24: 취미 | F24: ○ | I24: =600000/24 -> 25000 | J24: 배터리 수명 짧은 최신 무선 3년마다 기변 | K24: =300000/60 -> 5000 | L24: 유선 명기 + 블루투스 리시버 교체로 영구 사용 | M24: =K24-I24 -> -20000
D25: Self-hosting으로 구독료 제로화 | E25: IT | F25: ○ | G25: ○ | H25: IT 기술 강화 | I25: 50000 | J25: 스트리밍/클라우드 다중 구독 | K25: 5000 | L25: 전기세, 도메인 유지비 | M25: =K25-I25 -> -45000
C26: 서비스 비용 제거 | D26: 소형 포트 화분 구매후 육성 | E26: 취미 | F26: ○ | G26: ○ | H26: 식집사 체험 | I26: 30000 | J26: 대형 완성 화분 구매 및 폐기 반복 | K26: 3000 | L26: 소형 포트 육성 | M26: =K26-I26 -> -27000
D27: 조명, 힌지, 문고리 스스로 교환 | E27: 주 | F27: ○ | G27: ○ | H27: 부품선택 가능 | I27: 15000 | J27: 시공업체 출장비 및 마진 연환산 | K27: 3000 | L27: 인터넷 부품 원가 연환산 | M27: =K27-I27 -> -12000
D28: 비데 필터 자가 교환 | E28: 주 | F28: ○ | I28: 20000 | J28: 브랜드 렌탈 케어 서비스 | K28: 3000 | L28: 호환 필터 구입 | M28: =K28-I28 -> -17000
D29: 가스레인지 기름망 자가 세척 | E29: 주 | F29: ○ | I29: =100000/12 -> 8333.3333 | J29: 청소 서비스(년 2회, 회당 5만원) | K29: 1000 | L29: 세제 및 자가 노동 | M29: =K29-I29 -> -7333.3333
B30: 부품 교환 | C30: 부품을 교환하여 전체 set 수명 개선 | D30: PC에 ram/ssd 추가 | E30: IT | F30: ○ | G30: ○ | H30: 생산성 | I30: =1500000/24 -> 62500 | J30: 느려지면 완제품 교체 감가(150만원/2년) | K30: =100000/12 -> 8333.3333 | L30: 병목 부품만 업그레이드 | M30: =K30-I30 -> -54166.667 | P30: 아주 작은 부품 하나만 고장 나거나 느려져도 시스템 전체를 폐기하고 새로 구매함. | Q30: 병목(Bottleneck)이 발생한 노드만 정확히 짚어내어 교체(Patch)함으로써 전체 세트의 수명을 영구히 연장함.
D31: 전자제품 fuse 교환 | E31: 생활 | F31: ○ | I31: 10000 | J31: 공식 AS 호출 및 수리비 | K31: 200 | L31: 퓨즈 원가 | M31: =K31-I31 -> -9800
D32: 모바일 기기 케이스, 보호유리, 마우스 접점 등 | E32: 생활 | F32: ○ | I32: 15000 | J32: 대리점/브랜드 정품 구매 | K32: 2000 | L32: 부품 직구 | M32: =K32-I32 -> -13000
C33: 부품을 소모품화하여 사용감 개선 | D33: 다이소 신발깔창으로 자주 교환 | E33: 의 | F33: ○ | G33: ○ | H33: 쾌적함 | I33: 0 | J33: 신발 통교체 또는 세탁소 의뢰 | K33: 1000 | L33: 다이소 깔창 교체 | M33: =K33-I33 -> 1000
B34: 중고품 당근 | C34: 중고를 사서 초기 감가상각 비용 회피 | D34: 90~2000년대 오디오 컴포넌트 | E34: 취미 | F34: ○ | J34: 초기 신제품 감가상각 직격타 | K34: =7000000/120 -> 58333.333 | L34: 감가 끝난 명기 중고 방어 | M34: =K34-I34 -> 58333.333 | P34: 비닐도 안 뜯은 신제품의 초기 감가상각 비용을 온몸으로 두들겨 맞으며 자산을 탕진함. | Q34: 감가상각이 완전히 끝나 본질적인 가치만 남은 명작들을 당근마켓에서 주워와 생산성을 극상으로 레버리지함.
D35: 중형 카메라 및 렌즈 | E35: 취미 | F35: ○ | J35: 최신형 카메라 바디/렌즈 감가 | K35: =3500000/120 -> 29166.667 | L35: 중고품 소싱 및 재당근 방어 | M35: =K35-I35 -> 29166.667
D36: 맥 컴퓨터, 리눅스 미니 PC | E36: IT | F36: ○ | G36: ○ | H36: 생산성 | J36: 신형 출시마다 통기변 감가 | K36: =1300000/180 -> 7222.2222 | L36: 중고 맥/미니 PC 헌터 | M36: =K36-I36 -> 7222.2222
D37: 취미용품: 등산, 낚시, 골프채 등 | E37: 취미 | F37: ○ | I37: 100000 | J37: 유행 따라 신상 풀세트 구매 감가 | K37: 15000 | L37: 당근에서 검증된 중고 소싱 | M37: =K37-I37 -> -85000
D38: 보스턴 백 등 비일상 가방 | E38: 취미 | F38: ○ | I38: =250000/36 -> 6944.4444 | J38: 필요할 때마다 새 제품 구매 방치 | K38: =30000/36 -> 833.33333 | L38: 중고 거래 활용 | M38: =K38-I38 -> -6111.1111
D39: fitness 회원권 | E39: 취미 | F39: ○ | G39: ○ | H39: 건강 | I39: 100000 | J39: 정가 연간권 결제 후 유령 회원 | K39: =1200000*0.75*0.6/12 -> 45000 | L39: 당근마켓 양도권 활용 | M39: =K39-I39 -> -55000
B40: right spec | C40: 필요한 기능만 있는 제품을 구입하여 안쓰는 프리미엄 방지 | D40: 공기청정기: 샤오미+3rd party | E40: 주 | F40: ○ | I40: 40000 | J40: 하이엔드 브랜드 렌탈/구독료 | K40: =30000/60+10000*2/12 -> 2166.6667 | L40: 기본 스펙 + 호환 필터 자가교체 | M40: =K40-I40 -> -37833.333 | P40: 쓰지도 않는 프리미엄 기능과 센서가 덕지덕지 붙은 100만 원짜리 과보조 하이엔드 가전에 영혼을 빼앗김. | Q40: 콤팩트하고 이동성이 극대화된 기본 스펙만 취하고, 소모품은 호환 필터(3rd party)로 자가 관리하여 낭비를 차단함.
D41: 정수기: filter 자가 교환 | E41: 주 | F41: ○ | I41: 45000 | J41: 얼음/케어 포함 브랜드 렌탈 | K41: =198000/48+45000*2/12 -> 11625 | L41: 직수형 기본 스펙 + 자가 교체 | M41: =K41-I41 -> -33375
D42: 가습기: 샤오미 | E42: 주 | F42: ○ | I42: 20000 | J42: 복합식/과보조 기능 가습기 감가 | K42: =15000/24 -> 625 | L42: 자연기화식 기본 스펙 | M42: =K42-I42 -> -19375
...

Sheet 지출차이
A1: 구분 | B1: 방법 | C1: 포인트 | D1: 사례 | E1: 분야 | F1: 설계자 (Architect) | G1: 설계자_활동 | H1: 일반인 (Consumer) | I1: 일반인_활동 | J1: 노동자 (Laborer) | K1: 노동자_활동 | L1: 설계자-일반인 | M1: 설계자-노동자
A2: 비용 절감 | B2: 1타 N피 | C2: 한 제품 특징 여러 분야 적용 | D2: WD-40, 바세린, 니베아 크림 | E2: 생활 | F2: 1500 | G2: 범용 제품 1개로 해결 | H2: 15000 | I2: 용도별 전용 제품 복수 구매 | J2: 15000 | K2: 일반인과 동일하게 각각 구매 | L2: =F2-H2 -> -13500 | M2: =F2-J2 -> -13500
B3: positioning | C3: 저비용 position 확보 | D3: 중간에 낀 아파트 | E3: 주 | F3: 0 | G3: 옆/위/아래 아파트 온기 공유 | H3: 150000 | I3: 외벽 한기 제거용 가스 소비 | J3: 150000 | K3: 일반인과 동일한 가스 소비 | L3: =F3-H3 -> -150000 | M3: =F3-J3 -> -150000
B4: effectiveness | C4: 효과 발생 부분에만 비용 투입 | D4: 온수매트 | E4: 주 | F4: 30000 | G4: 동선 내 접촉 구역만 온수매트 | H4: 150000 | I4: 안 쓰는 공간까지 보일러 풀가동 | J4: 150000 | K4: 일반인과 동일하게 전체 가동 | L4: =F4-H4 -> -120000 | M4: =F4-J4 -> -120000
B5: alternative | C5: 동일 기능 가지는 대체품 활용 | D5: 전열교환기 프레임에 스틸자 사용 | E5: 주 | F5: 5000 | G5: 스틸자 5분 튜닝 무한 재활용 | H5: 60000 | I5: 전용 정품 프레임 구입 및 교환 | J5: 30000 | K5: 최저가 호환 프레임 검색에 2시간 소모 | L5: =F5-H5 -> -55000 | M5: =F5-J5 -> -25000
D6: 토마토로 과일 대체 | E6: 식 | F6: 20000 | G6: 영양가 높은 토마토 통일 | H6: 100000 | I6: 고가 제철/프리미엄 과일 구매 | J6: 60000 | K6: 마트 마감 세일 과자/과일 수령 노동 | L6: =F6-H6 -> -80000 | M6: =F6-J6 -> -40000
D7: 모니터 거치대 대신 백과사전 | E7: 생활 | F7: 0 | G7: 기존 물성 활용 | H7: 20000 | I7: 브랜드 전용 거치대 구매 감가 | J7: 10000 | K7: 당근 구형 거치대 직거래 거래 매몰 | L7: =F7-H7 -> -20000 | M7: =F7-J7 -> -10000
B8: DIY | C8: 고품질 제품 자작 | D8: 오디오용 멀티탭 생산 (굵은 전선) | E8: 취미 | F8: 10000 | G8: 부품 소싱 후 5분 내 결선 자작 | H8: 0 | I8: 완제품 구매 안 함 (관심 없음) | J8: 40000 | K8: 자작 카페 글 보며 주말 내내 납땜 노동 | L8: =F8-H8 -> 10000 | M8: =F8-J8 -> -30000
D9: 게샤 원두를 사서 드립백 자작 | E9: 기호 | F9: 21000 | G9: Top tier 원두 소싱 직접 추출 | H9: 150000 | I9: 브랜드 커피 전문점 무심코 이용 | J9: 60000 | K9: 가성비 저가 커피숍 찾아 원정 통근 | L9: =F9-H9 -> -129000 | M9: =F9-J9 -> -39000
D10: 드립백을 사서 고급티백 자작 | E10: 기호 | F10: 1500 | G10: 선물받은 차를 드립백으로 DIY | H10: 30000 | I10: 프리미엄 티 브랜드 완제품 구매 | J10: 15000 | K10: 마트 보급형 현미녹차 대량 구매 | L10: =F10-H10 -> -28500 | M10: =F10-J10 -> -13500
D11: LED 전구 + 한지로 조명만들기 | E11: 주 | F11: 200 | G11: 부품 소싱 및 5분 자작 | H11: 1000 | I11: 수입/디자이너 조명 구매 감가 | J11: 0 | K11: 인테리어 포기 (불 끄고 삶) | L11: =F11-H11 -> -800 | M11: =F11-J11 -> 200
D12: 소니 헤드폰 + 블루투스 리시버 | E12: 취미 | F12: 5000 | G12: 유선 명기 + 리시버 교체 영구 사용 | H12: 25000 | I12: 배터리 수명 짧은 무선 기기 기변 | J12: 15000 | K12: 짝퉁 가성비 무선 이어폰 잦은 고장교체 | L12: =F12-H12 -> -20000 | M12: =F12-J12 -> -10000
D13: Self-hosting으로 구독료 제로화 | E13: IT | F13: 5000 | G13: 전기세, 도메인 유지비 | H13: 50000 | I13: 스트리밍/클라우드 다중 구독 | J13: 20000 | K13: 무료 우회 결제/웹 서핑 시간 낭비 | L13: =F13-H13 -> -45000 | M13: =F13-J13 -> -15000
C14: 서비스 비용 제거 | D14: 소형 포트 화분 구매 후 육성 | E14: 취미 | F14: 3000 | G14: 소형 포트 육성 | H14: 30000 | I14: 대형 완성 화분 구매 및 폐기 반복 | J14: 15000 | K14: 산이나 들에서 흙 파오기 육체 노동 | L14: =F14-H14 -> -27000 | M14: =F14-J14 -> -12000
D15: 조명, 힌지, 문고리 스스로 교환 | E15: 주 | F15: 3000 | G15: 인터넷 부품 원가 연환산 (5분 컷) | H15: 15000 | I15: 시공업체 출장비 및 마진 연환산 | J15: 3000 | K15: 주말 하루 통째로 반납하여 시공 노동 | L15: =F15-H15 -> -12000 | M15: =F15-J15 -> 0
D16: 비데 필터 자가 교환 | E16: 주 | F16: 3000 | G16: 호환 필터 구입 (원터치 1분 교체) | H16: 20000 | I16: 브랜드 렌탈 케어 서비스 상납 | J16: 3000 | K16: 스패너 들고 고전하며 필터 수동 조립 | L16: =F16-H16 -> -17000 | M16: =F16-J16 -> 0
D17: 가스레인지 기름망 자가 세척 | E17: 주 | F17: 1000 | G17: 과탄산소다 전용 세제 5분 불림 세척 | H17: 8333 | I17: 청소 업체 호출 서비스 | J17: 1000 | K17: 철수세미로 손목 나갈 때까지 박박 문지름 | L17: =F17-H17 -> -7333 | M17: =F17-J17 -> 0
B18: 부품 교환 | C18: 부품 교환하여 전체 set 수명 개선 | D18: PC에 ram/ssd 추가 | E18: IT | F18: 8333 | G18: 병목 부품만 깔끔하게 정밀 업그레이드 | H18: 62500 | I18: 느려지면 완제품 교체 감가 상납 | J18: 30000 | K18: 사양 맞추려 밤새 커뮤니티 정독 노동 | L18: =F18-H18 -> -54167 | M18: =F18-J18 -> -21667
D19: 전자제품 fuse 교환 | E19: 생활 | F19: 200 | G19: 퓨즈 원가 직구 세팅 | H19: 10000 | I19: 공식 AS 호출비 및 수리비 지불 | J19: 5000 | K19: 동네 전포 다 뒤져가며 부품 구하러 다님 | L19: =F19-H19 -> -9800 | M19: =F19-J19 -> -4800
D20: 모바일 기기 케이스, 보호유리 보수 | E20: 생활 | F20: 2000 | G20: 부품 직구 사전 구비 | H20: 15000 | I20: 대리점/브랜드 정품 비싸게 구매 | J20: 2000 | K20: 가성비 알리 배송 한 달 기다림 대기 매몰 | L20: =F20-H20 -> -13000 | M20: =F20-J20 -> 0
C21: 부품을 소모품화하여 사용감 개선 | D21: 다이소 신발깔창으로 자주 교환 | E21: 의 | F21: 1000 | G21: 다이소 깔창 교체로 쾌적 유지 | H21: 0 | I21: 일반인은 미수행 (신발 조기 폐기) | J21: 0 | K21: 노동자도 미수행 (그냥 참고 신음) | L21: =F21-H21 -> 1000 | M21: =F21-J21 -> 1000
B22: 중고품 당근 | C22: 중고 사서 초기 감가상각 회피 | D22: 90~2000년대 오디오 컴포넌트 | E22: 취미 | F22: 58333 | G22: 감가 끝난 명기 중고 데이터 기반 방어 | H22: 0 | I22: 일반인 기준 제외 (관심 없음) | J22: 20000 | K22: 당근 키워드 알림 보며 무한 잠복 스트레스받다가 최신 국내, 중국산 오디오 구입 | L22: =F22-H22 -> 58333 | M22: =F22-J22 -> 38333
D23: 중형 카메라 및 렌즈 | E23: 취미 | F23: 29167 | G23: 중고품 소싱 및 명징한 재당근 방어 | H23: 0 | I23: 일반인 기준 제외 (관심 없음) | J23: 10000 | K23: 밤낮으로 장터 매물 사기 검증 스트레스로 slr카메라, 렌즈 구입후 호환 지옥 | L23: =F23-H23 -> 29167 | M23: =F23-J23 -> 19167
D24: 맥 컴퓨터, 리눅스 미니 PC | E24: IT | F24: 7222 | G24: 중고 맥/미니 PC 가성비 헌터 | H24: 0 | I24: 일반인 기준 제외 (관심 없음) | J24: 5000 | K24: 고장 난 벽돌 매물 주워와 고치느라 고생 | L24: =F24-H24 -> 7222 | M24: =F24-J24 -> 2222
D25: 취미용품: 등산, 낚시, 골프채 등 | E25: 취미 | F25: 15000 | G25: 당근에서 검증된 명품 중고 소싱 | H25: 100000 | I25: 유행 따라 신상 풀세트 구매 감가 | J25: 40000 | K25: 상태 불량 매물 잘못 사서 이중 지출 고생 | L25: =F25-H25 -> -85000 | M25: =F25-J25 -> -25000
D26: 보스턴 백 등 비일상 가방 | E26: 취미 | F26: 833 | G26: 중고 거래 영리한 활용 | H26: 6944 | I26: 필요할 때마다 새 제품 구매 방치 | J26: 4000 | K26: 중고 직거래하러 왕복 1시간 운전 노동 | L26: =F26-H26 -> -6111 | M26: =F26-J26 -> -3167
D27: fitness 회원권 | E27: 취미 | F27: 45000 | G27: 당근마켓 양도권 스마트 활용 | H27: 100000 | I27: 정가 연간권 결제 후 유령 회원 | J27: 60000 | K27: 헬스장 거리 멀어도 무조건 싼 곳 결제 | L27: =F27-H27 -> -55000 | M27: =F27-J27 -> -15000
B28: right spec | C28: 필요한 기능만 있는 제품 구입 | D28: 공기청정기: 샤오미+3rd party | E28: 주 | F28: 2167 | G28: 기본 스펙 + 호환 필터 자가교체 | H28: 40000 | I28: 하이엔드 브랜드 렌탈/구독료 상납 | J28: 10000 | K28: 필터 물세척해서 쓰려다 성능 망가뜨림 | L28: =F28-H28 -> -37833 | M28: =F28-J28 -> -7833
D29: 정수기: filter 자가 교환 | E29: 주 | F29: 11625 | G29: 직수형 기본 스펙 + 자가 교체 | H29: 45000 | I29: 얼음/케어 포함 브랜드 렌탈 상납 | J29: 20000 | K29: 생수 최저가 검색 후 매번 문앞 이동 노동 | L29: =F29-H29 -> -33375 | M29: =F29-J29 -> -8375
D30: 가습기: 샤오미 | E30: 주 | F30: 625 | G30: 자연기화식 기본 스펙 설정 분해 세척 | H30: 20000 | I30: 복합식/과보조 기능 가습기 감가 상납 | J30: 10000 | K30: 수동 세척 힘든 구조 매일 닦느라 고생 | L30: =F30-H30 -> -19375 | M30: =F30-J30 -> -9375
D31: 마우스: 로지텍 기본, 키보드: 독거미 | E31: IT | F31: 1250 | G31: 가성비 최적화 명기 기기 세팅 | H31: 15000 | I31: 게이밍/프리미엄 잦은 교체 감가 | J31: 8000 | K31: 피시방 중고 마우스 주워와 고쳐 씀 | L31: =F31-H31 -> -13750 | M31: =F31-J31 -> -6750
D32: 내의: 국산 대량 구입 통일 | E32: 의 | F32: 3000 | G32: 품질 좋은 국산 대량 구매 통일 | H32: 20000 | I32: 브랜드/백화점 내의 낱개 구매 누수 | J32: 10000 | K32: 다이소 초저가 내의 사서 금방 늘어남 | L32: =F32-H32 -> -17000 | M32: =F32-J32 -> -7000
D33: 이너: 아울렛 매대 기능성 구입 | E33: 의 | F33: 8333 | G33: 매대 기능성 의류 원가 소싱 | H33: 33333 | I33: 신상/브랜드 이너웨어 구매 페이로드 | J33: 15000 | K33: 구제 시장 뒤져가며 옷 고르는 시간 낭비 | L33: =F33-H33 -> -25000 | M33: =F33-J33 -> -6667
D34: 모니터는 120hz, 4K로 스펙 통일 | E34: IT | F34: 10000 | G34: Eizo 등 최적 스펙 통일 방어 | H34: 30000 | I34: 오버스펙 게이밍/브랜드 감가 상납 | J34: 20000 | K34: 중고 깨진 모니터 들고 와 수리 시도 | L34: =F34-H34 -> -20000 | M34: =F34-J34 -> -10000
D35: 아이패드는 일반형 wifi로 | E35: IT | F35: 8667 | G35: 일반형 본질 스펙 영리한 유지 | H35: 41667 | I35: 프로/셀룰러 사고 밥 먹을 때 유튜브 거치 | J35: 20000 | K35: 가성비 중국산 탭 샀다가 벽돌 되어 방치 | L35: =F35-H35 -> -33000 | M35: =F35-J35 -> -11333
C36: 필요한 기능에 지불 | D36: 놋쇠 수저, 세라믹 식기 | E36: 식 | F36: 1667 | G36: 반영구적 실질 기능 명품 식기 | H36: 15000 | I36: 유행 타는 식기 세트 잦은 기변 누수 | J36: 5000 | K36: 다이소 플라스틱 식기 유해물질 노출 위험 | L36: =F36-H36 -> -13333 | M36: =F36-J36 -> -3333
C37: 고성능 PC로 IT 생산성 강화 | D37: Mac studio 등 CPU/RAM 집중투자 | E37: IT | F37: 30000 | G37: 64GB RAM 코어 집중 롱런 설계 | H37: 0 | I37: 일반인 기준 제외 (윈도우 놋북 한대 끝) | J37: 10000 | K37: 조립 PC 호환성 꼬여 주말 내내 포맷 반복 | L37: =F37-H37 -> 30000 | M37: =F37-J37 -> 20000
B38: not over change | C38: 실질적 내구도 보고 소모품 교환 | D38: 엔진오일: 데이터 기반 보충/적기교환 | E38: 생활 | F38: 11250 | G38: 데이터 기반 보충 후 적기 교환 | H38: 20000 | I38: 센터의 과잉 정비 스크립트 그대로 수행 | J38: 15000 | K38: 공임나라 최저가 찾으려 원정 정비 노동 | L38: =F38-H38 -> -8750 | M38: =F38-J38 -> -3750
D39: 비브람 밑창 교환 | E39: 의 | F39: 7167 | G39: 마모 전 선제적 보강 수명 연장 | H39: 16667 | I39: 밑창 닳으면 신발 통째 폐기 및 재구입 | J39: 10000 | K39: 셀프작업하다 집안에 냄새 가득 노동 | L39: =F39-H39 -> -9500 | M39: =F39-J39 -> -2833
B40: 유지보수 | C40: 사전 유지보수 통한 고장 방지 | D40: 가죽제품 정기 컨디셔닝 | E40: 의 | F40: 2000 | G40: 컨디셔너 도포로 반영구적 유지 | H40: 30000 | I40: 갈라지고 부패하여 통폐기/재구입 | J40: 15000 | K40: 다이소 구두약으로 문지르다 가죽 망가뜨림 | L40: =F40-H40 -> -28000 | M40: =F40-J40 -> -13000
...

Sheet 자산차이
A1: 목차 | B1: 내용 | C1: 페이지
A2: 서문 | B2: 집필 목적: 설명이 아닌 공감대 형성, 계산/미리알림 양식 공유를 통한 실행 관리 | C2: 3 | F2: 천원 | G2: 기초 | H2: 지출항목 연계 | J2: 수익 | K2: random | L2: -0.02 | M2: 기말
A3: 지출 관리 | B3: 개념, 3개의 타입, 지출 형태 및 결과표 | C3: 10 | F3: year | G3: 일반인 | H3: 노동자 | I3: 설계자 | J3: 일반인 | K3: 노동자 | L3: 설계자 | M3: 일반인 | N3: 노동자 | O3: 설계자
A4: 지출관리 방법론 | B4: 비용절감 14개, 관리 3개 각각에 대한 설명 및 사례 제시 | C4: 34 | F4: 2 | G4: =D29*12 -> 13200 | H4: =E29*12 -> 24000 | I4: =F29*12 -> 37200 | J4: =G4*RANDBETWEEN(-10, 10)/100 -> 924 | K4: =H4*RANDBETWEEN(-10, 10)/100 -> -1680 | L4: =I4*L$2 -> -744 | M4: =G4+J4 -> 14124 | N4: =H4+K4 -> 22320 | O4: =I4+L4 -> 36456
A5: 시간 관리 | B5: 개념, 3개의 타입, 지출 형태 및 결과표 | C5: 4 | F5: 3 | G5: =G$4+M4 -> 27324 | H5: =H$4+N4 -> 46320 | I5: =I$4+O4 -> 73656 | J5: =G5*RANDBETWEEN(-10, 10)/100 -> -2185.92 | K5: =H5*RANDBETWEEN(-10, 10)/100 -> -2779.2 | L5: =I5*L$2 -> -1473.12 | M5: =G5+J5 -> 25138.08 | N5: =H5+K5 -> 43540.8 | O5: =I5+L5 -> 72182.88
A6: Resource | B6: 관리 결과 시간/비용 변화 도표(as is vs. to be를 input, consumption, balance로 표현) | C6: 2 | F6: 4 | G6: =G$4+M5 -> 38338.08 | H6: =H$4+N5 -> 67540.8 | I6: =I$4+O5 -> 109382.88 | J6: =G6*RANDBETWEEN(-10, 10)/100 -> 766.7616 | K6: =H6*RANDBETWEEN(-10, 10)/100 -> -3377.04 | L6: =I6*L$2 -> -2187.6576 | M6: =G6+J6 -> 39104.842 | N6: =H6+K6 -> 64163.76 | O6: =I6+L6 -> 107195.22
A7: 시간 | B7: 활용 개념과 5대 과제 | C7: 3 | F7: 5 | G7: =G$4+M6 -> 52304.842 | H7: =H$4+N6 -> 88163.76 | I7: =I$4+O6 -> 144395.22 | J7: =G7*RANDBETWEEN(-10, 10)/100 -> 0 | K7: =H7*RANDBETWEEN(-10, 10)/100 -> 8816.376 | L7: =I7*L$2 -> -2887.9044 | M7: =G7+J7 -> 52304.842 | N7: =H7+K7 -> 96980.136 | O7: =I7+L7 -> 141507.32
B8: 선순환 효과 | C8: 4 | F8: 6 | G8: =G$4+M7 -> 65504.842 | H8: =H$4+N7 -> 120980.14 | I8: =I$4+O7 -> 178707.32 | J8: =G8*RANDBETWEEN(-10, 10)/100 -> -655.04842 | K8: =H8*RANDBETWEEN(-10, 10)/100 -> -12098.014 | L8: =I8*L$2 -> -3574.1464 | M8: =G8+J8 -> 64849.793 | N8: =H8+K8 -> 108882.12 | O8: =I8+L8 -> 175133.17
B9: 나에 대한 선물주기 | C9: 2 | F9: 7 | G9: =G$4+M8 -> 78049.793 | H9: =H$4+N8 -> 132882.12 | I9: =I$4+O8 -> 212333.17 | J9: =G9*RANDBETWEEN(-10, 10)/100 -> 780.49793 | K9: =H9*RANDBETWEEN(-10, 10)/100 -> -2657.6424 | L9: =I9*L$2 -> -4246.6634 | M9: =G9+J9 -> 78830.291 | N9: =H9+K9 -> 130224.48 | O9: =I9+L9 -> 208086.51
B10: 합계 | C10: =SUM(C2:C9) -> 62 | F10: 8 | G10: =G$4+M9 -> 92030.291 | H10: =H$4+N9 -> 154224.48 | I10: =I$4+O9 -> 245286.51 | J10: =G10*RANDBETWEEN(-10, 10)/100 -> 4601.5146 | K10: =H10*RANDBETWEEN(-10, 10)/100 -> -4626.7344 | L10: =I10*L$2 -> -4905.7302 | M10: =G10+J10 -> 96631.806 | N10: =H10+K10 -> 149597.75 | O10: =I10+L10 -> 240380.78
F11: 9 | G11: =G$4+M10 -> 109831.81 | H11: =H$4+N10 -> 173597.75 | I11: =I$4+O10 -> 277580.78 | J11: =G11*RANDBETWEEN(-10, 10)/100 -> -2196.6361 | K11: =H11*RANDBETWEEN(-10, 10)/100 -> 1735.9775 | L11: =I11*L$2 -> -5551.6156 | M11: =G11+J11 -> 107635.17 | N11: =H11+K11 -> 175333.72 | O11: =I11+L11 -> 272029.16
F12: 10 | G12: =G$4+M11 -> 120835.17 | H12: =H$4+N11 -> 199333.72 | I12: =I$4+O11 -> 309229.16 | J12: =G12*RANDBETWEEN(-10, 10)/100 -> 6041.7585 | K12: =H12*RANDBETWEEN(-10, 10)/100 -> -9966.6862 | L12: =I12*L$2 -> -6184.5832 | M12: =G12+J12 -> 126876.93 | N12: =H12+K12 -> 189367.04 | O12: =I12+L12 -> 303044.58
F13: 11 | G13: =G$4+M12 -> 140076.93 | H13: =H$4+N12 -> 213367.04 | I13: =I$4+O12 -> 340244.58 | J13: =G13*RANDBETWEEN(-10, 10)/100 -> 2801.5386 | K13: =H13*RANDBETWEEN(-10, 10)/100 -> 12802.022 | L13: =I13*L$2 -> -6804.8916 | M13: =G13+J13 -> 142878.47 | N13: =H13+K13 -> 226169.06 | O13: =I13+L13 -> 333439.69
F14: 12 | G14: =G$4+M13 -> 156078.47 | H14: =H$4+N13 -> 250169.06 | I14: =I$4+O13 -> 370639.69 | J14: =G14*RANDBETWEEN(-10, 10)/100 -> -14047.062 | K14: =H14*RANDBETWEEN(-10, 10)/100 -> -20013.525 | L14: =I14*L$2 -> -7412.7938 | M14: =G14+J14 -> 142031.4 | N14: =H14+K14 -> 230155.53 | O14: =I14+L14 -> 363226.89
F15: 13 | G15: =G$4+M14 -> 155231.4 | H15: =H$4+N14 -> 254155.53 | I15: =I$4+O14 -> 400426.89 | J15: =G15*RANDBETWEEN(-10, 10)/100 -> 9313.8843 | K15: =H15*RANDBETWEEN(-10, 10)/100 -> 12707.777 | L15: =I15*L$2 -> -8008.5379 | M15: =G15+J15 -> 164545.29 | N15: =H15+K15 -> 266863.31 | O15: =I15+L15 -> 392418.36
F16: 14 | G16: =G$4+M15 -> 177745.29 | H16: =H$4+N15 -> 290863.31 | I16: =I$4+O15 -> 429618.36 | J16: =G16*RANDBETWEEN(-10, 10)/100 -> 5332.3587 | K16: =H16*RANDBETWEEN(-10, 10)/100 -> 8725.8993 | L16: =I16*L$2 -> -8592.3671 | M16: =G16+J16 -> 183077.65 | N16: =H16+K16 -> 299589.21 | O16: =I16+L16 -> 421025.99
F17: 15 | G17: =G$4+M16 -> 196277.65 | H17: =H$4+N16 -> 323589.21 | I17: =I$4+O16 -> 458225.99 | J17: =G17*RANDBETWEEN(-10, 10)/100 -> 17664.988 | K17: =H17*RANDBETWEEN(-10, 10)/100 -> -16179.461 | L17: =I17*L$2 -> -9164.5198 | M17: =G17+J17 -> 213942.64 | N17: =H17+K17 -> 307409.75 | O17: =I17+L17 -> 449061.47
F18: 16 | G18: =G$4+M17 -> 227142.64 | H18: =H$4+N17 -> 331409.75 | I18: =I$4+O17 -> 486261.47 | J18: =G18*RANDBETWEEN(-10, 10)/100 -> -6814.2791 | K18: =H18*RANDBETWEEN(-10, 10)/100 -> 33140.975 | L18: =I18*L$2 -> -9725.2294 | M18: =G18+J18 -> 220328.36 | N18: =H18+K18 -> 364550.72 | O18: =I18+L18 -> 476536.24
F19: 17 | G19: =G$4+M18 -> 233528.36 | H19: =H$4+N18 -> 388550.72 | I19: =I$4+O18 -> 513736.24 | J19: =G19*RANDBETWEEN(-10, 10)/100 -> -21017.552 | K19: =H19*RANDBETWEEN(-10, 10)/100 -> 38855.072 | L19: =I19*L$2 -> -10274.725 | M19: =G19+J19 -> 212510.8 | N19: =H19+K19 -> 427405.8 | O19: =I19+L19 -> 503461.51
F20: 18 | G20: =G$4+M19 -> 225710.8 | H20: =H$4+N19 -> 451405.8 | I20: =I$4+O19 -> 540661.51 | J20: =G20*RANDBETWEEN(-10, 10)/100 -> -2257.108 | K20: =H20*RANDBETWEEN(-10, 10)/100 -> -40626.522 | L20: =I20*L$2 -> -10813.23 | M20: =G20+J20 -> 223453.7 | N20: =H20+K20 -> 410779.28 | O20: =I20+L20 -> 529848.28
F21: 19 | G21: =G$4+M20 -> 236653.7 | H21: =H$4+N20 -> 434779.28 | I21: =I$4+O20 -> 567048.28 | J21: =G21*RANDBETWEEN(-10, 10)/100 -> -2366.537 | K21: =H21*RANDBETWEEN(-10, 10)/100 -> -26086.757 | L21: =I21*L$2 -> -11340.966 | M21: =G21+J21 -> 234287.16 | N21: =H21+K21 -> 408692.52 | O21: =I21+L21 -> 555707.32
F22: 20 | G22: =G$4+M21 -> 247487.16 | H22: =H$4+N21 -> 432692.52 | I22: =I$4+O21 -> 592907.32 | J22: =G22*RANDBETWEEN(-10, 10)/100 -> -4949.7432 | K22: =H22*RANDBETWEEN(-10, 10)/100 -> 17307.701 | L22: =I22*L$2 -> -11858.146 | M22: =G22+J22 -> 242537.42 | N22: =H22+K22 -> 450000.22 | O22: =I22+L22 -> 581049.17
F23: 21 | G23: =G$4+M22 -> 255737.42 | H23: =H$4+N22 -> 474000.22 | I23: =I$4+O22 -> 618249.17 | J23: =G23*RANDBETWEEN(-10, 10)/100 -> -2557.3742 | K23: =H23*RANDBETWEEN(-10, 10)/100 -> -9480.0044 | L23: =I23*L$2 -> -12364.983 | M23: =G23+J23 -> 253180.04 | N23: =H23+K23 -> 464520.22 | O23: =I23+L23 -> 605884.19
D25: 일반인 | E25: 노동자 | F25: 설계자
C26: 수입 | D26: 5000 | E26: 5000 | F26: 5000
C27: 제어 지출 | D27: 2400 | E27: 1500 | F27: 400
C28: 고정 지출 | D28: 1500 | E28: 1500 | F28: 1500
C29: Balance | D29: =D26-D27-D28 -> 1100 | E29: =E26-E27-E28 -> 2000 | F29: =F26-F27-F28 -> 3100

Sheet 매핑초안
A1: 대분류 | B1: 소분류 | C1: 항목명 | D1: 방법 | E1: 설계자 접근 핵심 | F1: 설계자_월 | G1: 일반인_월 | H1: 노동자_월 | I1: 싱글남 | J1: 싱글여 | K1: 커플 | L1: 가족(육아) | M1: 시니어 | N1: 평가
A2: 주거 | B2: 위치/임대 | C2: 위치 포지셔닝 | D2: positioning | E2: 교통+생활권 균형 잡힌 중간 위치 선택 | F2: 0 | G2: 150000 | H2: 150000 | I2: ○ | J2: ○ | K2: ○ | L2: ○ | M2: ○ | N2: drop: 너무 오지랍임
A3: 주거 | B3: 냉난방 | C3: 효과 부위만 투자 | D3: effectiveness | E3: 온수매트로 방 전체 난방 대신 국소 난방 | F3: 30000 | G3: 150000 | H3: 150000 | I3: ○ | J3: ○ | K3: ○ | L3: ○ | M3: ○
A4: 주거 | B4: 가구/인테리어 | C4: 대체품·중고 | D4: alternative | E4: 전열교환기 프레임에 스틸자 / 이케아+중고 조합 | F4: 5000 | G4: 60000 | H4: 30000 | I4: ○ | J4: ○ | K4: ○ | L4: ○ | M4: ○
A5: 주거 | B5: 가구/인테리어 | C5: ikea mulig | D5: right spec | E5: 이케아 mulig 행거는 저가, 최소 공간, 건조대 활용 가능 | F5: =19800/12/10 -> 165 | G5: =250000/12/2 -> 10416.667 | H5: =160000/12/2 -> 6666.6667 | I5: ○ | J5: ○ | K5: ○ | L5: ○ | M5: ○ | N5: 신규
A6: 주거 | B6: 공기청정기 | C6: right spec | D6: right spec | E6: 샤오미 + 3rd party 필터 직접 교체 | F6: 2167 | G6: 40000 | H6: 10000 | I6: ○ | J6: ○ | K6: ○ | L6: ○ | M6: ○
A7: 주거 | B7: 정수기 | C7: 부품 교환 | D7: 부품 교환 | E7: 필터 직구 후 자가 교환 (렌탈 불필요) | F7: 11625 | G7: 45000 | H7: 20000 | I7: ○ | J7: ○ | K7: ○ | L7: ○ | M7: ○
A8: 주거 | B8: 가습기 | C8: right spec | D8: right spec | E8: 샤오미 저가형으로 충분 | F8: 625 | G8: 20000 | H8: 10000 | I8: ○ | J8: ○ | K8: ○ | L8: ○ | M8: ○
A9: 주거 | B9: 조명 | C9: DIY | D9: DIY | E9: LED 전구 + 한지로 직접 제작 | F9: 200 | G9: 1000 | H9: 0 | I9: ○ | J9: ○ | K9: ○ | L9: ○ | M9: ○
A10: 주거 | B10: 유지보수 (조명·힌지·문고리) | C10: 직접 교환 | D10: 유지보수 | E10: 공구 구비 후 셀프 교체 | F10: 3000 | G10: 15000 | H10: 3000 | I10: ○ | J10: ○ | K10: ○ | L10: ○ | M10: ○
A11: 주거 | B11: 비데 필터 | C11: 자가 교환 | D11: 부품 교환 | E11: 필터 직구 후 직접 교체 | F11: 3000 | G11: 20000 | H11: 3000 | I11: ○ | J11: ○ | K11: ○ | L11: ○ | M11: ○
A12: 주거 | B12: 가스레인지 | C12: 자가 세척 | D12: 유지보수 | E12: 기름망 직접 세척 (청소업체 불필요) | F12: 1000 | G12: 8333 | H12: 1000 | I12: ○ | J12: ○ | K12: ○ | L12: ○ | M12: ○
A13: 주거 | B13: 통신비 | C13: 공기계+알뜰폰 | D13: right spec | E13: 공기계 구입 후 알뜰폰 조합 / 아이폰 계약 만료 후 장기 사용 | F13: 15000 | G13: 80000 | H13: 40000 | I13: ○ | J13: ○ | K13: ○ | L13: ○ | M13: ○
A14: 주거 | B14: 청소·세탁용품 | C14: condensate | D14: condensate | E14: 농축 세제 소분 / 다회용 행주로 키친타올 대체 | F14: 5000 | G14: 30000 | H14: 15000 | I14: ○ | J14: ○ | K14: ○ | L14: ○ | M14: ○
A15: 주거 | B15: 청소기 | C15: right spec | D15: right spec | E15: 신일 등 저가 무선 청소기 (다이슨 대비 동일 효과) | F15: 15000 | G15: 80000 | H15: 30000 | I15: ○ | J15: ○ | K15: ○ | L15: ○ | M15: ○
A16: 주거 | B16: 침구 | C16: 솜이불 기준 | D16: right spec | E16: 솜이불 사용 (no goose down) — 내용연한 유사, 촉감 좋고 털 날림 없음 | F16: 5000 | G16: 50000 | H16: 20000 | I16: ○ | J16: ○ | K16: ○ | L16: ○ | M16: ○
A17: 교통 | B17: 자동차 보험 | C17: 마일리지+운전점수+블랙박스 | D17: right spec | E17: 다이렉트 보험 + 마일리지·운전점수·블랙박스 할인 적용 | F17: 30000 | G17: 80000 | H17: 60000 | I17: ○ | J17: ○ | K17: ○ | L17: ○ | M17: △
... A24: 식 | B24: 건강보조제·비타민 | C24: 흡수율 기반 최소 섭취 | D24: right spec | E24: 성분표 기반 선택 / 흡수율 감안해 직관 대비 1/2만 섭취 | F24: 15000 | G24: 60000 | H24: 30000 | I24: ○ | J24: ○ | K24: ○ | L24: △ | M24: ○
A25: 의 | B25: 속옷·내의 (남성) | C25: 대량 통일 구입 | D25: simplify | E25: 국산 국민내의 대량 구입(좋은 사람들, BYC 등) | F25: 3000 | G25: 20000 | H25: 10000 | I25: ○
A26: 의 | B26: 아우터·이너 | C26: 아울렛 | D26: right spec | E26: 기능성 이너 아울렛 매대 구입 | F26: 8333 | G26: 33333 | H26: 15000 | I26: ○ | J26: ○ | K26: ○ | L26: ○ | M26: ○
A27: 의 | B27: 신발 밑창 | C27: 수선 | D27: 유지보수 | E27: 비브람 밑창 교환으로 신발 수명 연장 | F27: 7167 | G27: 16667 | H27: 10000 | I27: ○ | J27: ○ | K27: ○ | L27: ○ | M27: ○
A28: 의 | B28: 가죽제품 | C28: 유지보수 | D28: 유지보수 | E28: 가죽 정기 컨디셔닝으로 수명 연장 | F28: 2000 | G28: 30000 | H28: 15000 | I28: ○ | J28: ○ | K28: ○ | L28: ○ | M28: ○
A29: 의 | B29: 개인용품 (샴푸·바디워시) | C29: 소분 용기 활용 | D29: sharing | E29: 대용량 구입 후 소분 용기 이용 | F29: 1000 | G29: 15000 | H29: 5000 | I29: ○ | J29: ○ | K29: ○ | L29: ○ | M29: ○
A30: 의 | B30: 면도기·면도날 (남성) | C30: 질레트+고무판+클렌징폼 | D30: right spec | E30: 고품질 질레트 대량 구입 + 고무판으로 날 수명 연장 + 클렌징폼을 면도크림 대용 | F30: 3000 | G30: 15000 | H30: 8000 | I30: ○
A31: 의 | B31: 화장품 기초 (스킨·로션·세럼) | C31: 성분 기반 더마 브랜드 | D31: right spec | E31: 닥터지·코스알엑스·바이오더마·세타필 등 (백화점 프리미엄 불필요) | J31: ○ | K31: ○ | L31: ○
A32: 의 | B32: 화장품 색조 | C32: minimalist 1세트 | D32: simplify | E32: daily 1세트로 통일 / 단종 임박 할인 구입 | J32: ○ | K32: ○ | L32: ○
A33: 의 | B33: 헤어케어 (염색·펌) | C33: 홈 트리트먼트 병행 | D33: not over change | E33: 미용실 주기 늘리기 + 홈 트리트먼트로 보완 | J33: ○ | K33: ○ | L33: ○
A34: 건강 | B34: 치과 예방 | C34: 물리적 예방 관리 | D34: effectiveness | E34: 이쑤시개·치실·물분사기로 일상 물리적 관리 → 치과 방문 빈도 최소화 | F34: 5000 | G34: 30000 | H34: 10000 | I34: ○ | J34: ○ | K34: ○ | L34: ○ | M34: ○
A35: 건강 | B35: 안경·렌즈 | C35: 고가 1개 장기 사용 | D35: right spec | E35: 고품질 안경 1개 장기 사용 / 렌즈는 온라인 직구 | F35: 5000 | G35: 30000 | H35: 15000 | I35: ○ | J35: ○ | K35: ○ | L35: ○ | M35: ○ | N35: 렌즈 구매 요령 필요한가? 보통은 안경 or 라식 아닌가?
A36: 기호 | B36: 커피 | C36: DIY | D36: DIY | E36: 게샤 등 고품질 원두 직접 드립 / 드립백 자작 or 드립 필터만 구매 | F36: 22500 | G36: 180000 | H36: 75000 | I36: ○ | J36: ○ | K36: ○ | L36: ○ | M36: ○
A37: 기호 | B37: 차·음료 | C37: condensate | D37: condensate | E37: 녹차 티백도 좋지만, 티백 구입하여 자작하면 품질이 더 나음 | F37: 5000 | G37: 80000 | H37: 40000 | I37: ○ | J37: ○ | K37: ○ | L37: ○ | M37: ○
A38: 기호 | B38: 주류 | C38: right spec | D38: right spec | E38: 독주(안동소주, VSOP 꼬냑) +얼음 : 낮은 부피, 안주 과식 방지 | F38: 30000 | G38: 120000 | H38: 60000 | I38: ○ | J38: △ | K38: △ | L38: X | M38: △
A39: 기호 | B39: 간식·견과류 | C39: simplify | D39: simplify | E39: 캐슈넛·야채크래커 등 통일하여 대용량 구입 | F39: 20000 | G39: 200000 | H39: 100000 | I39: ○ | J39: ○ | K39: ○ | L39: △ | M39: ○
A40: 취미 | B40: 오디오 | C40: 중고+DIY | D40: 중고품 당근 | E40: 90~2000년대 중고 오디오 컴포넌트 | F40: 58333 | G40: 0 | H40: 20000 | I40: ○ | J40: △ | K40: △ | L40: X | M40: △
A41: 취미 | B41: 사진·카메라 | C41: 중고 | D41: 중고품 당근 | E41: 중형 카메라·렌즈 중고 구입 | F41: 29167 | G41: 0 | H41: 10000 | I41: ○ | J41: ○ | K41: △ | L41: X | M41: △
A42: 취미 | B42: 스포츠 용품 | C42: 중고+right spec | D42: 중고품 당근 | E42: 등산·낚시·골프채 중고 구입 | F42: 15000 | G42: 100000 | H42: 40000 | I42: ○ | J42: ○ | K42: ○ | L42: △ | M42: ○
A43: 취미 | B43: 비일상 가방 | C43: 중고 | D43: 중고품 당근 | E43: 보스턴백 등 중고 구입 | F43: 833 | G43: 6944 | H43: 4000 | I43: ○ | J43: ○ | K43: ○ | L43: △ | M43: ○
A44: 취미 | B44: 피트니스 | C44: right spec | D44: positioning | E44: 아파트 헬스장 | F44: 45000 | G44: 100000 | H44: 60000 | I44: ○ | J44: ○ | K44: ○ | L44: △ | M44: ○
A45: 취미 | B45: 피트니스 | C45: 의사 결정 후 구입 | D45: flexibility | E45: 연간 회원권 중고 구입 | N45: 추가
A46: 취미 | B46: 반려식물 | C46: DIY | D46: DIY | E46: 소형 포트 화분 직접 육성 | F46: 3000 | G46: 30000 | H46: 15000 | I46: ○ | J46: ○ | K46: ○ | L46: ○ | M46: ○
...

Sheet 매핑v2
A1: 대분류 | B1: 소분류 | C1: approach | D1: 실행방법 | E1: 설계자_월 | F1: 일반인_월 | G1: 노동자_월 | H1: 싱글남 | I1: 싱글여 | J1: 커플 | K1: 가족(육아) | L1: 시니어
A2: 주거 | B2: 냉난방 | C2: effectiveness | D2: 온수매트로 방 전체 난방 대신 국소 난방 | E2: 30000 | F2: 150000 | G2: 150000 | H2: ○ | I2: ○ | J2: ○ | K2: ○ | L2: ○
A3: 주거 | B3: 가구/인테리어 | C3: alternative | D3: 전열교환기 프레임에 스틸자 / 이케아+중고 조합 | E3: 5000 | F3: 60000 | G3: 30000 | H3: ○ | I3: ○ | J3: ○ | K3: ○ | L3: ○
A4: 주거 | B4: 가구/인테리어 | C4: right spec | D4: 이케아 mulig 행거: 저가·최소 공간·건조대 겸용 | E4: 165 | F4: 10417 | G4: 6667 | H4: ○ | I4: ○ | J4: ○ | K4: ○ | L4: ○
A5: 주거 | B5: 공기청정기 | C5: right spec | D5: 샤오미 + 3rd party 필터 직접 교체 | E5: 2167 | F5: 40000 | G5: 10000 | H5: ○ | I5: ○ | J5: ○ | K5: ○ | L5: ○
A6: 주거 | B6: 정수기 | C6: 부품 교환 | D6: 필터 직구 후 자가 교환 (렌탈 불필요) | E6: 11625 | F6: 45000 | G6: 20000 | H6: ○ | I6: ○ | J6: ○ | K6: ○ | L6: ○
A7: 주거 | B7: 가습기 | C7: right spec | D7: 샤오미 저가형으로 충분 | E7: 625 | F7: 20000 | G7: 10000 | H7: ○ | I7: ○ | J7: ○ | K7: ○ | L7: ○
A8: 주거 | B8: 조명 | C8: DIY | D8: LED 전구 + 한지로 직접 제작 | E8: 200 | F8: 1000 | G8: 0 | H8: ○ | I8: ○ | J8: ○ | K8: ○ | L8: ○
A9: 주거 | B9: 유지보수 (조명·힌지·문고리) | C9: 유지보수 | D9: 공구 구비 후 셀프 교체 | E9: 3000 | F9: 15000 | G9: 3000 | H9: ○ | I9: ○ | J9: ○ | K9: ○ | L9: ○
A10: 주거 | B10: 비데 필터 | C10: 부품 교환 | D10: 필터 직구 후 직접 교체 | E10: 3000 | F10: 20000 | G10: 3000 | H10: ○ | I10: ○ | J10: ○ | K10: ○ | L10: ○
A11: 주거 | B11: 가스레인지 | C11: 유지보수 | D11: 기름망 직접 세척 (청소업체 불필요) | E11: 1000 | F11: 8333 | G11: 1000 | H11: ○ | I11: ○ | J11: ○ | K11: ○ | L11: ○
A12: 주거 | B12: 통신비 | C12: right spec | D12: 공기계 구입 후 알뜰폰 조합 / 아이폰 계약 만료 후 장기 사용 | E12: 15000 | F12: 80000 | G12: 40000 | H12: ○ | I12: ○ | J12: ○ | K12: ○ | L12: ○
A13: 주거 | B13: 청소·세탁용품 | C13: condensate | D13: 농축 세제 소분 / 다회용 행주로 키친타올 대체 | E13: 5000 | F13: 30000 | G13: 15000 | H13: ○ | I13: ○ | J13: ○ | K13: ○ | L13: ○
... A29: 의 | B29: 면도기·면도날 (남성) | C29: right spec | D29: 고품질 질레트 대량 구입 + 고무판으로 날 수명 연장 + 클렌징폼을 면도크림 대용 | E29: 3000 | F29: 15000 | G29: 8000 | H29: ○ | I29: X | J29: ○ | K29: ○ | L29: ○
A30: 의 | B30: 화장품 기초 (스킨·로션·세럼) | C30: right spec | D30: 닥터지·코스알엑스·바이오더마·세타필 등 (백화점 프리미엄 불필요) | I30: ○ | J30: ○ | K30: ○
A31: 의 | B31: 화장품 색조 | C31: simplify | D31: daily 1세트로 통일 / 단종 임박 할인 구입 | I31: ○ | J31: ○ | K31: ○
A32: 의 | B32: 헤어케어 (염색·펌) | C32: not over change | D32: 미용실 주기 늘리기 + 홈 트리트먼트로 보완 | I32: ○ | J32: ○ | K32: ○
A33: 건강 | B33: 치과 예방 | C33: effectiveness | D33: 이쑤시개·치실·물분사기로 일상 물리적 관리 → 치과 방문 빈도 최소화 | E33: 5000 | F33: 30000 | G33: 10000 | H33: ○ | I33: ○ | J33: ○ | K33: ○ | L33: ○
A34: 건강 | B34: 안경·렌즈 | C34: right spec | D34: 고품질 안경 1개 장기 사용 / 렌즈는 온라인 직구 | E34: 5000 | F34: 30000 | G34: 15000 | H34: ○ | I34: ○ | J34: ○ | K34: ○ | L34: ○
A35: 기호 | B35: 커피 | C35: DIY | D35: 게샤 등 고품질 원두 직접 드립 / 드립백 자작 또는 드립 필터만 구매 | E35: 22500 | F35: 180000 | G35: 75000 | H35: ○ | I35: ○ | J35: ○ | K35: ○ | L35: ○
A36: 기호 | B36: 차·음료 | C36: condensate | D36: 티백 직접 구입해 우리기 — 기성 티백보다 품질 우수 | E36: 5000 | F36: 80000 | G36: 40000 | H36: ○ | I36: ○ | J36: ○ | K36: ○ | L36: ○
A37: 기호 | B37: 주류 | C37: right spec | D37: 독주(안동소주·VSOP 꼬냑) + 얼음 — 부피 낮고 안주 과식 방지 | E37: 30000 | F37: 120000 | G37: 60000 | H37: ○ | I37: △ | J37: △ | K37: X | L37: △
A38: 기호 | B38: 간식·견과류 | C38: simplify | D38: 캐슈넛·야채크래커 등 통일하여 대용량 구입 | E38: 20000 | F38: 200000 | G38: 100000 | H38: ○ | I38: ○ | J38: ○ | K38: △ | L38: ○
A39: 취미 | B39: 오디오 | C39: 중고품 당근 | D39: 90~2000년대 중고 오디오 컴포넌트 (당근·세컨웨이브) | E39: 58333 | F39: 0 | G39: 20000 | H39: ○ | I39: △ | J39: △ | K39: X | L39: △
A40: 취미 | B40: 사진·카메라 | C40: 중고품 당근 | D40: 중형 카메라·렌즈 중고 구입 | E40: 29167 | F40: 0 | G40: 10000 | H40: ○ | I40: ○ | J40: △ | K40: X | L40: △
A41: 취미 | B41: 스포츠 용품 | C41: 중고품 당근 | D41: 등산·낚시·골프채 중고 구입 | E41: 15000 | F41: 100000 | G41: 40000 | H41: ○ | I41: ○ | J41: ○ | K41: △ | L41: ○
A42: 취미 | B42: 비일상 가방 | C42: 중고품 당근 | D42: 보스턴백 등 비일상 가방 중고 구입 | E42: 833 | F42: 6944 | G42: 4000 | H42: ○ | I42: ○ | J42: ○ | K42: △ | L42: ○
A43: 취미 | B43: 피트니스 | C43: positioning | D43: 아파트 헬스장 / 구청 헬스장 이용 | E43: 45000 | F43: 100000 | G43: 60000 | H43: ○ | I43: ○ | J43: ○ | K43: △ | L43: ○
A44: 취미 | B44: 피트니스 | C44: 중고품 당근 | D44: 연간 회원권 중고 구입 (체험 후 지속 여부 결정 선행) | H44: ○ | I44: ○ | J44: ○ | K44: △ | L44: ○
A45: 취미 | B45: 반려식물 | C45: DIY | D45: 소형 포트 화분 직접 육성 | E45: 3000 | F45: 30000 | G45: 15000 | H45: ○ | I45: ○ | J45: ○ | K45: ○ | L45: ○
A46: 취미 | B46: 여성 취미 (공예·요가·필라테스) | C46: right spec | D46: 원데이 클래스로 먼저 체험 → 정기 등록 결정 | I46: ○ | J46: ○ | K46: ○
A47: 취미 | B47: 반려동물 사료 | C47: right spec | D47: 성분표 기반 선택 / 대용량 직구 | E47: 30000 | F47: 60000 | G47: 40000 | H47: △ | I47: △ | J47: △ | K47: △ | L47: △
A48: 취미 | B48: 반려동물 병원 | C48: effectiveness | D48: 예방접종·정기검진 준수로 치료비 예방 | E48: 10000 | F48: 30000 | G48: 15000 | H48: △ | I48: △ | J48: △ | K48: △ | L48: △
A49: 취미 | B49: 반려동물 미용 | C49: DIY | D49: 셀프 목욕·빗질 (반려동물과의 놀이 시간으로 인식) | E49: 5000 | F49: 30000 | G49: 10000 | H49: △ | I49: △ | J49: △ | K49: △ | L49: △
A50: IT | B50: PC 업그레이드 | C50: 부품 교환 | D50: RAM/SSD 추가로 본체 교체 없이 수명 연장 | E50: 8333 | F50: 62500 | G50: 30000 | H50: ○ | I50: ○ | J50: ○ | K50: ○ | L50: △
A51: IT | B51: Self-hosting | C51: DIY | D51: Nextcloud 등으로 클라우드 구독료 제로화 | E51: 5000 | F51: 50000 | G51: 20000 | H51: ○ | I51: △ | J51: △ | K51: X | L51: △
A52: IT | B52: 마우스·키보드 | C52: right spec | D52: 로지텍 기본·독거미 키보드 | E52: 1250 | F52: 15000 | G52: 8000 | H52: ○ | I52: ○ | J52: ○ | K52: ○ | L52: △
A53: IT | B53: 모니터 | C53: right spec | D53: 120hz 4K 한번 구입 후 장기 사용 | E53: 10000 | F53: 30000 | G53: 20000 | H53: ○ | I53: ○ | J53: ○ | K53: ○ | L53: ○
A54: IT | B54: 태블릿 (아이패드) | C54: right spec | D54: 일반형 wifi 모델 | E54: 8667 | F54: 41667 | G54: 20000 | H54: ○ | I54: ○ | J54: ○ | K54: ○ | L54: ○
A55: IT | B55: 고성능 PC·Mac | C55: right spec | D55: Mac Studio CPU/RAM에만 집중투자 / 구형은 재활용 | E55: 30000 | F55: 0 | G55: 10000 | H55: ○ | I55: ○ | J55: ○ | K55: ○ | L55: △
...

Sheet 비용분석
B1: 대분류 | C1: 소분류 | D1: approach | E1: 실행방법_설계자 | F1: 실행방법_일반인 | G1: 실행방법_노동자 | H1: 유형 | I1: 설계자_가격 | J1: 설계자_내용연수 | K1: 설계자_사용시간/빈도 | L1: 설계자_사용량 | M1: 설계자_단가 | N1: 설계자_소모품가격 | O1: 설계자_소모품내용연수 | P1: 설계자_월 | Q1: 유형_일반인 | R1: 일반인_가격 | S1: 일반인_내용연수 | T1: 일반인_사용시간 | U1: 일반인_사용량 | V1: 일반인_단가 | W1: 일반인_소모품가격 | X1: 일반인_소모품내용연수 | Y1: 일반인_월 | Z1: 유형_노동자 | AA1: 노동자_가격 | AB1: 노동자_내용연수 | AC1: 노동자_사용시간 | AD1: 노동자_사용량 | AE1: 노동자_단가 | AF1: 노동자_소모품가격 | AG1: 노동자_소모품내용연수 | AH1: 노동자_월 | AI1: 싱글남_설계자 | AJ1: 싱글남_설계자_확인 | AK1: 싱글남_일반인 | AL1: 싱글남_일반인_확인 | AM1: 싱글남_노동자 | AN1: 싱글남_노동자_확인 | AO1: 싱글여_설계자 | AP1: 싱글여_설계자_확인 | AQ1: 싱글여_일반인 | AR1: 싱글여_일반인_확인 | AS1: 싱글여_노동자 | AT1: 싱글여_노동자_확인 | AU1: 커플_설계자 | AV1: 커플_설계자_확인 | AW1: 커플_일반인 | AX1: 커플_일반인_확인 | AY1: 커플_노동자 | AZ1: 커플_노동자_확인 | BA1: 가족(육아)_설계자 | BB1: 가족(육아)_설계자_확인 | BC1: 가족(육아)_일반인 | BD1: 가족(육아)_일반인_확인 | BE1: 가족(육아)_노동자 | BF1: 가족(육아)_노동자_확인 | BG1: 시니어_설계자 | BH1: 시니어_설계자_확인 | BI1: 시니어_일반인 | BJ1: 원가절감_설계자 | BK1: 원가절감_일반인 | BL1: 원가절감_노동자 | BM1: 가치제고_설계자 | BN1: 가치제고_일반인 | BO1: 가치제고_노동자
A2: 1 | B2: 주거 | C2: 냉난방 | D2: effectiveness | E2: 온수매트로 방 전체 난방 대신 국소 난방 | F2: 안 쓰는 공간까지 보일러 풀가동 | G2: 일반인과 동일하게 전체 가동 | H2: 4 | I2: 250000 | J2: 7 | K2: 210 | L2: 0.25 | M2: 120 | P2: =IF($H2=1,IF(AND(I2<>"",J2<>""),I2/J2/12,""),IF($H2=2,IF(AND(K2<>"",L2<>"",M2<>""),K2*L2*M2,""),IF($H2=3,IF(AND(N2<>"",O2<>""),N2/O2/12,""),IF($H2=4,IF(AND(I2<>"",J2<>""),I2/J2/12,0)+IF(AND(K2<>"",L2<>"",M2<>""),K2*L2*M2,0),IF($H2=5,IF(AND(I2<>"",J2<>""),I2/J2/12,0)+IF(AND(N2<>"",O2<>""),N2/O2/12,0),IF($H2=6,IF(AND(K2<>"",L2<>"",M2<>""),K2*L2*M2,0)+IF(AND(N2<>"",O2<>""),N2/O2/12,0),"")))))) -> 9276.1905 | Q2: 2 | T2: =8*30 -> 240 | U2: 2.2 | V2: 900 | Y2: =IF($Q2=1,IF(AND(R2<>"",S2<>""),R2/S2/12,""),IF($Q2=2,IF(AND(T2<>"",U2<>"",V2<>""),T2*U2*V2,""),IF($Q2=3,IF(AND(W2<>"",X2<>""),W2/X2/12,""),IF($Q2=4,IF(AND(R2<>"",S2<>""),R2/S2/12,0)+IF(AND(T2<>"",U2<>"",V2<>""),T2*U2*V2,0),IF($Q2=5,IF(AND(R2<>"",S2<>""),R2/S2/12,0)+IF(AND(W2<>"",X2<>""),W2/X2/12,0),IF($Q2=6,IF(AND(T2<>"",U2<>"",V2<>""),T2*U2*V2,0)+IF(AND(W2<>"",X2<>""),W2/X2/12,0),"")))))) -> 475200 | Z2: 2 | AC2: =8*30 -> 240 | AD2: 2.2 | AE2: 900 | AH2: =IF($Z2=1,IF(AND(AA2<>"",AB2<>""),AA2/AB2/12,""),IF($Z2=2,IF(AND(AC2<>"",AD2<>"",AE2<>""),AC2*AD2*AE2,""),IF($Z2=3,IF(AND(AF2<>"",AG2<>""),AF2/AG2/12,""),IF($Z2=4,IF(AND(AA2<>"",AB2<>""),AA2/AB2/12,0)+IF(AND(AC2<>"",AD2<>"",AE2<>""),AC2*AD2*AE2,0),IF($Z2=5,IF(AND(AA2<>"",AB2<>""),AA2/AB2/12,0)+IF(AND(AF2<>"",AG2<>""),AF2/AG2/12,0),IF($Z2=6,IF(AND(AC2<>"",AD2<>"",AE2<>""),AC2*AD2*AE2,0)+IF(AND(AF2<>"",AG2<>""),AF2/AG2/12,0),"")))))) -> 475200 | AI2: =IF(매핑v2!H2="○",P2,"") -> 9276.1905 | AJ2: =IF(매핑v2!H2="○","○","X") -> ○ | AK2: =IF(매핑v2!H2="○",Y2,"") -> 475200 | AL2: =IF(매핑v2!H2="○","○","X") -> ○ | AM2: =IF(매핑v2!H2="○",AH2,"") -> 475200 | AN2: =IF(매핑v2!H2="○","○","X") -> ○ | AO2: =IF(매핑v2!I2="○",P2,"") -> 9276.1905 | AP2: =IF(매핑v2!I2="○","○","X") -> ○ | AQ2: =IF(매핑v2!I2="○",Y2,"") -> 475200 | AR2: =IF(매핑v2!I2="○","○","X") -> ○ | AS2: =IF(매핑v2!I2="○",AH2,"") -> 475200 | AT2: =IF(매핑v2!I2="○","○","X") -> ○ | AU2: =IF(매핑v2!J2="○",P2,"") -> 9276.1905 | AV2: =IF(매핑v2!J2="○","○","X") -> ○ | AW2: =IF(매핑v2!J2="○",Y2,"") -> 475200 | AX2: =IF(매핑v2!J2="○","○","X") -> ○ | AY2: =IF(매핑v2!J2="○",AH2,"") -> 475200 | AZ2: =IF(매핑v2!J2="○","○","X") -> ○ | BA2: =IF(매핑v2!K2="○",P2,"") -> 9276.1905 | BB2: =IF(매핑v2!K2="○","○","X") -> ○ | BC2: =IF(매핑v2!K2="○",Y2,"") -> 475200 | BD2: =IF(매핑v2!K2="○","○","X") -> ○ | BE2: =IF(매핑v2!K2="○",AH2,"") -> 475200 | BF2: =IF(매핑v2!K2="○","○","X") -> ○ | BG2: =IF(매핑v2!L2="○",P2,"") -> 9276.1905 | BH2: =IF(매핑v2!L2="○","○","X") -> ○ | BI2: =IF(매핑v2!L2="○",Y2,"") -> 475200 | BJ2: ○ | BK2: X | BL2: X | BM2: ○ | BN2: X | BO2: X
A3: 2 | B3: 주거 | C3: 가구/인테리어 | D3: alternative | E3: 아파트 전열교환기 필터 구입 및 스틸자로 프레임 강화 | F3: 프레임 부식으로 전열교환기 교환 | G3: 최저가 호환 프레임 검색에 2시간 소모, 결국 교환 | H3: 5 | I3: 5000 | J3: 5 | N3: 100000 | O3: 4 | P3: =IF($H3=1,IF(AND(I3<>"",J3<>""),I3/J3/12,""),IF($H3=2,IF(AND(K3<>"",L3<>"",M3<>""),K3*L3*M3,""),IF($H3=3,IF(AND(N3<>"",O3<>""),N3/O3/12,""),IF($H3=4,IF(AND(I3<>"",J3<>""),I3/J3/12,0)+IF(AND(K3<>"",L3<>"",M3<>""),K3*L3*M3,0),IF($H3=5,IF(AND(I3<>"",J3<>""),I3/J3/12,0)+IF(AND(N3<>"",O3<>""),N3/O3/12,0),IF($H3=6,IF(AND(K3<>"",L3<>"",M3<>""),K3*L3*M3,0)+IF(AND(N3<>"",O3<>""),N3/O3/12,0),"")))))) -> 2166.6667 | Q3: 5 | R3: 3000000 | S3: 5 | Y3: =IF($Q3=1,IF(AND(R3<>"",S3<>""),R3/S3/12,""),IF($Q3=2,IF(AND(T3<>"",U3<>"",V3<>""),T3*U3*V3,""),IF($Q3=3,IF(AND(W3<>"",X3<>""),W3/X3/12,""),IF($Q3=4,IF(AND(R3<>"",S3<>""),R3/S3/12,0)+IF(AND(T3<>"",U3<>"",V3<>""),T3*U3*V3,0),IF($Q3=5,IF(AND(R3<>"",S3<>""),R3/S3/12,0)+IF(AND(W3<>"",X3<>""),W3/X3/12,0),IF($Q3=6,IF(AND(T3<>"",U3<>"",V3<>""),T3*U3*V3,0)+IF(AND(W3<>"",X3<>""),W3/X3/12,0),"")))))) -> 50000 | Z3: 5 | AA3: 3000000 | AB3: 5 | AH3: =IF($Z3=1,IF(AND(AA3<>"",AB3<>""),AA3/AB3/12,""),IF($Z3=2,IF(AND(AC3<>"",AD3<>"",AE3<>""),AC3*AD3*AE3,""),IF($Z3=3,IF(AND(AF3<>"",AG3<>""),AF3/AG3/12,""),IF($Z3=4,IF(AND(AA3<>"",AB3<>""),AA3/AB3/12,0)+IF(AND(AC3<>"",AD3<>"",AE3<>""),AC3*AD3*AE3,0),IF($Z3=5,IF(AND(AA3<>"",AB3<>""),AA3/AB3/12,0)+IF(AND(AF3<>"",AG3<>""),AF3/AG3/12,0),IF($Z3=6,IF(AND(AC3<>"",AD3<>"",AE3<>""),AC3*AD3*AE3,0)+IF(AND(AF3<>"",AG3<>""),AF3/AG3/12,0),"")))))) -> 50000 | AI3: =IF(매핑v2!H3="○",P3,"") -> 2166.6667 | AJ3: =IF(매핑v2!H3="○","○","X") -> ○ | AK3: =IF(매핑v2!H3="○",Y3,"") -> 50000 | AL3: =IF(매핑v2!H3="○","○","X") -> ○ | AM3: =IF(매핑v2!H3="○",AH3,"") -> 50000 | AN3: =IF(매핑v2!H3="○","○","X") -> ○ | AO3: =IF(매핑v2!I3="○",P3,"") -> 2166.6667 | AP3: =IF(매핑v2!I3="○","○","X") -> ○ | AQ3: =IF(매핑v2!I3="○",Y3,"") -> 50000 | AR3: =IF(매핑v2!I3="○","○","X") -> ○ | AS3: =IF(매핑v2!I3="○",AH3,"") -> 50000 | AT3: =IF(매핑v2!I3="○","○","X") -> ○ | AU3: =IF(매핑v2!J3="○",P3,"") -> 2166.6667 | AV3: =IF(매핑v2!J3="○","○","X") -> ○ | AW3: =IF(매핑v2!J3="○",Y3,"") -> 50000 | AX3: =IF(매핑v2!J3="○","○","X") -> ○ | AY3: =IF(매핑v2!J3="○",AH3,"") -> 50000 | AZ3: =IF(매핑v2!J3="○","○","X") -> ○ | BA3: =IF(매핑v2!K3="○",P3,"") -> 2166.6667 | BB3: =IF(매핑v2!K3="○","○","X") -> ○ | BC3: =IF(매핑v2!K3="○",Y3,"") -> 50000 | BD3: =IF(매핑v2!K3="○","○","X") -> ○ | BE3: =IF(매핑v2!K3="○",AH3,"") -> 50000 | BF3: =IF(매핑v2!K3="○","○","X") -> ○ | BG3: =IF(매핑v2!L3="○",P3,"") -> 2166.6667 | BH3: =IF(매핑v2!L3="○","○","X") -> ○ | BI3: =IF(매핑v2!L3="○",Y3,"") -> 50000 | BJ3: ○ | BK3: X | BL3: ○ | BM3: ○ | BN3: X | BO3: X
A4: 3 | B4: 주거 | C4: 가구/인테리어 | D4: right spec | E4: 이케아 mulig 행거: 저가·최소 공간·건조대 겸용 | F4: 모든 옷은 붙박이 장에 걸고, 건조기 구입 | G4: 플라스틱 서랍장에 모든 옷을 접어서 넣고, 저가 건조대로 공간 희생 | H4: 1 | I4: 20000 | J4: 10 | P4: =IF($H4=1,IF(AND(I4<>"",J4<>""),I4/J4/12,""),IF($H4=2,IF(AND(K4<>"",L4<>"",M4<>""),K4*L4*M4,""),IF($H4=3,IF(AND(N4<>"",O4<>""),N4/O4/12,""),IF($H4=4,IF(AND(I4<>"",J4<>""),I4/J4/12,0)+IF(AND(K4<>"",L4<>"",M4<>""),K4*L4*M4,0),IF($H4=5,IF(AND(I4<>"",J4<>""),I4/J4/12,0)+IF(AND(N4<>"",O4<>""),N4/O4/12,0),IF($H4=6,IF(AND(K4<>"",L4<>"",M4<>""),K4*L4*M4,0)+IF(AND(N4<>"",O4<>""),N4/O4/12,0),"")))))) -> 166.66667 | Q4: 1 | R4: 15000000 | S4: 8 | W4: 1200000 | X4: 2 | Y4: =IF($Q4=1,IF(AND(R4<>"",S4<>""),R4/S4/12,""),IF($Q4=2,IF(AND(T4<>"",U4<>"",V4<>""),T4*U4*V4,""),IF($Q4=3,IF(AND(W4<>"",X4<>""),W4/X4/12,""),IF($Q4=4,IF(AND(R4<>"",S4<>""),R4/S4/12,0)+IF(AND(T4<>"",U4<>"",V4<>""),T4*U4*V4,0),IF($Q4=5,IF(AND(R4<>"",S4<>""),R4/S4/12,0)+IF(AND(W4<>"",X4<>""),W4/X4/12,0),IF($Q4=6,IF(AND(T4<>"",U4<>"",V4<>""),T4*U4*V4,0)+IF(AND(W4<>"",X4<>""),W4/X4/12,0),"")))))) -> 156250 | Z4: 1 | AA4: =60000+40000 -> 100000 | AB4: 2 | AF4: 1200000 | AG4: 2 | AH4: =IF($Z4=1,IF(AND(AA4<>"",AB4<>""),AA4/AB4/12,""),IF($Z4=2,IF(AND(AC4<>"",AD4<>"",AE4<>""),AC4*AD4*AE4,""),IF($Z4=3,IF(AND(AF4<>"",AG4<>""),AF4/AG4/12,""),IF($Z4=4,IF(AND(AA4<>"",AB4<>""),AA4/AB4/12,0)+IF(AND(AC4<>"",AD4<>"",AE4<>""),AC4*AD4*AE4,0),IF($Z4=5,IF(AND(AA4<>"",AB4<>""),AA4/AB4/12,0)+IF(AND(AF4<>"",AG4<>""),AF4/AG4/12,0),IF($Z4=6,IF(AND(AC4<>"",AD4<>"",AE4<>""),AC4*AD4*AE4,0)+IF(AND(AF4<>"",AG4<>""),AF4/AG4/12,0),"")))))) -> 4166.6667 | AI4: =IF(매핑v2!H4="○",P4,"") -> 166.66667 | AJ4: =IF(매핑v2!H4="○","○","X") -> ○ | AK4: =IF(매핑v2!H4="○",Y4,"") -> 156250 | AL4: =IF(매핑v2!H4="○","○","X") -> ○ | AM4: =IF(매핑v2!H4="○",AH4,"") -> 4166.6667 | AN4: =IF(매핑v2!H4="○","○","X") -> ○ | AO4: =IF(매핑v2!I4="○",P4,"") -> 166.66667 | AP4: =IF(매핑v2!I4="○","○","X") -> ○ | AQ4: =IF(매핑v2!I4="○",Y4,"") -> 156250 | AR4: =IF(매핑v2!I4="○","○","X") -> ○ | AS4: =IF(매핑v2!I4="○",AH4,"") -> 4166.6667 | AT4: =IF(매핑v2!I4="○","○","X") -> ○ | AU4: =IF(매핑v2!J4="○",P4,"") -> 166.66667 | AV4: =IF(매핑v2!J4="○","○","X") -> ○ | AW4: =IF(매핑v2!J4="○",Y4,"") -> 156250 | AX4: =IF(매핑v2!J4="○","○","X") -> ○ | AY4: =IF(매핑v2!J4="○",AH4,"") -> 4166.6667 | AZ4: =IF(매핑v2!J4="○","○","X") -> ○ | BA4: =IF(매핑v2!K4="○",P4,"") -> 166.66667 | BB4: =IF(매핑v2!K4="○","○","X") -> ○ | BC4: =IF(매핑v2!K4="○",Y4,"") -> 156250 | BD4: =IF(매핑v2!K4="○","○","X") -> ○ | BE4: =IF(매핑v2!K4="○",AH4,"") -> 4166.6667 | BF4: =IF(매핑v2!K4="○","○","X") -> ○ | BG4: =IF(매핑v2!L4="○",P4,"") -> 166.66667 | BH4: =IF(매핑v2!L4="○","○","X") -> ○ | BI4: =IF(매핑v2!L4="○",Y4,"") -> 156250 | BJ4: ○ | BK4: X | BL4: ○ | BM4: ○ | BN4: X | BO4: X
A5: 4 | B5: 주거 | C5: 공기청정기 | D5: right spec | E5: 샤오미 + 3rd party 필터 직접 교체 | F5: 하이엔드 브랜드 렌탈/구독료 상납 | G5: 필터 물세척해서 쓰려다 공기청정기 망가뜨림 | H5: 5 | I5: 40000 | J5: 5 | N5: 10000 | O5: 1 | P5: =IF($H5=1,IF(AND(I5<>"",J5<>""),I5/J5/12,""),IF($H5=2,IF(AND(K5<>"",L5<>"",M5<>""),K5*L5*M5,""),IF($H5=3,IF(AND(N5<>"",O5<>""),N5/O5/12,""),IF($H5=4,IF(AND(I5<>"",J5<>""),I5/J5/12,0)+IF(AND(K5<>"",L5<>"",M5<>""),K5*L5*M5,0),IF($H5=5,IF(AND(I5<>"",J5<>""),I5/J5/12,0)+IF(AND(N5<>"",O5<>""),N5/O5/12,0),IF($H5=6,IF(AND(K5<>"",L5<>"",M5<>""),K5*L5*M5,0)+IF(AND(N5<>"",O5<>""),N5/O5/12,0),"")))))) -> 1500 | Q5: 5 | T5: 1 | U5: 1 | V5: 48000 | W5: 60000 | X5: 0.5 | Y5: =IF($Q5=1,IF(AND(R5<>"",S5<>""),R5/S5/12,""),IF($Q5=2,IF(AND(T5<>"",U5<>"",V5<>""),T5*U5*V5,""),IF($Q5=3,IF(AND(W5<>"",X5<>""),W5/X5/12,""),IF($Q5=4,IF(AND(R5<>"",S5<>""),R5/S5/12,0)+IF(AND(T5<>"",U5<>"",V5<>""),T5*U5*V5,0),IF($Q5=5,IF(AND(R5<>"",S5<>""),R5/S5/12,0)+IF(AND(W5<>"",X5<>""),W5/X5/12,0),IF($Q5=6,IF(AND(T5<>"",U5<>"",V5<>""),T5*U5*V5,0)+IF(AND(W5<>"",X5<>""),W5/X5/12,0),"")))))) -> 10000 | Z5: 5 | AA5: 300000 | AB5: 1 | AF5: 60000 | AG5: 1 | AH5: =IF($Z5=1,IF(AND(AA5<>"",AB5<>""),AA5/AB5/12,""),IF($Z5=2,IF(AND(AC5<>"",AD5<>"",AE5<>""),AC5*AD5*AE5,""),IF($Z5=3,IF(AND(AF5<>"",AG5<>""),AF5/AG5/12,""),IF($Z5=4,IF(AND(AA5<>"",AB5<>""),AA5/AB5/12,0)+IF(AND(AC5<>"",AD5<>"",AE5<>""),AC5*AD5*AE5,0),IF($Z5=5,IF(AND(AA5<>"",AB5<>""),AA5/AB5/12,0)+IF(AND(AF5<>"",AG5<>""),AF5/AG5/12,0),IF($Z5=6,IF(AND(AC5<>"",AD5<>"",AE5<>""),AC5*AD5*AE5,0)+IF(AND(AF5<>"",AG5<>""),AF5/AG5/12,0),"")))))) -> 30000 | AI5: =IF(매핑v2!H5="○",P5,"") -> 1500 | AJ5: =IF(매핑v2!H5="○","○","X") -> ○ | AK5: =IF(매핑v2!H5="○",Y5,"") -> 10000 | AL5: =IF(매핑v2!H5="○","○","X") -> ○ | AM5: =IF(매핑v2!H5="○",AH5,"") -> 30000 | AN5: =IF(매핑v2!H5="○","○","X") -> ○ | AO5: =IF(매핑v2!I5="○",P5,"") -> 1500 | AP5: =IF(매핑v2!I5="○","○","X") -> ○ | AQ5: =IF(매핑v2!I5="○",Y5,"") -> 10000 | AR5: =IF(매핑v2!I5="○","○","X") -> ○ | AS5: =IF(매핑v2!I5="○",AH5,"") -> 30000 | AT5: =IF(매핑v2!I5="○","○","X") -> ○ | AU5: =IF(매핑v2!J5="○",P5,"") -> 1500 | AV5: =IF(매핑v2!J5="○","○","X") -> ○ | AW5: =IF(매핑v2!J5="○",Y5,"") -> 10000 | AX5: =IF(매핑v2!J5="○","○","X") -> ○ | AY5: =IF(매핑v2!J5="○",AH5,"") -> 30000 | AZ5: =IF(매핑v2!J5="○","○","X") -> ○ | BA5: =IF(매핑v2!K5="○",P5,"") -> 1500 | BB5: =IF(매핑v2!K5="○","○","X") -> ○ | BC5: =IF(매핑v2!K5="○",Y5,"") -> 10000 | BD5: =IF(매핑v2!K5="○","○","X") -> ○ | BE5: =IF(매핑v2!K5="○",AH5,"") -> 30000 | BF5: =IF(매핑v2!K5="○","○","X") -> ○ | BG5: =IF(매핑v2!L5="○",P5,"") -> 1500 | BH5: =IF(매핑v2!L5="○","○","X") -> ○ | BI5: =IF(매핑v2!L5="○",Y5,"") -> 10000 | BJ5: ○ | BK5: X | BL5: ○ | BM5: ○ | BN5: ○ | BO5: X
A6: 5 | B6: 주거 | C6: 정수기 | D6: 부품 교환 | E6: 필터 직구 후 자가 교환 (렌탈 불필요) | F6: 얼음/케어 포함 브랜드 렌탈 상납 | G6: 생수 최저가 검색 후 매번 문앞 이동 노동 | H6: 5 | I6: 200000 | J6: 5 | N6: 50000 | O6: 1 | P6: =IF($H6=1,IF(AND(I6<>"",J6<>""),I6/J6/12,""),IF($H6=2,IF(AND(K6<>"",L6<>"",M6<>""),K6*L6*M6,""),IF($H6=3,IF(AND(N6<>"",O6<>""),N6/O6/12,""),IF($H6=4,IF(AND(I6<>"",J6<>""),I6/J6/12,0)+IF(AND(K6<>"",L6<>"",M6<>""),K6*L6*M6,0),IF($H6=5,IF(AND(I6<>"",J6<>""),I6/J6/12,0)+IF(AND(N6<>"",O6<>""),N6/O6/12,0),IF($H6=6,IF(AND(K6<>"",L6<>"",M6<>""),K6*L6*M6,0)+IF(AND(N6<>"",O6<>""),N6/O6/12,0),"")))))) -> 7500 | Q6: 5 | T6: 1 | U6: 1 | V6: 45000 | Y6: =IF($Q6=1,IF(AND(R6<>"",S6<>""),R6/S6/12,""),IF($Q6=2,IF(AND(T6<>"",U6<>"",V6<>""),T6*U6*V6,""),IF($Q6=3,IF(AND(W6<>"",X6<>""),W6/X6/12,""),IF($Q6=4,IF(AND(R6<>"",S6<>""),R6/S6/12,0)+IF(AND(T6<>"",U6<>"",V6<>""),T6*U6*V6,0),IF($Q6=5,IF(AND(R6<>"",S6<>""),R6/S6/12,0)+IF(AND(W6<>"",X6<>""),W6/X6/12,0),IF($Q6=6,IF(AND(T6<>"",U6<>"",V6<>""),T6*U6*V6,0)+IF(AND(W6<>"",X6<>""),W6/X6/12,0),"")))))) -> 0 | Z6: 2 | AC6: 4 | AD6: 1 | AE6: 12000 | AH6: =IF($Z6=1,IF(AND(AA6<>"",AB6<>""),AA6/AB6/12,""),IF($Z6=2,IF(AND(AC6<>"",AD6<>"",AE6<>""),AC6*AD6*AE6,""),IF($Z6=3,IF(AND(AF6<>"",AG6<>""),AF6/AG6/12,""),IF($Z6=4,IF(AND(AA6<>"",AB6<>""),AA6/AB6/12,0)+IF(AND(AC6<>"",AD6<>"",AE6<>""),AC6*AD6*AE6,0),IF($Z6=5,IF(AND(AA6<>"",AB6<>""),AA6/AB6/12,0)+IF(AND(AF6<>"",AG6<>""),AF6/AG6/12,0),IF($Z6=6,IF(AND(AC6<>"",AD6<>"",AE6<>""),AC6*AD6*AE6,0)+IF(AND(AF6<>"",AG6<>""),AF6/AG6/12,0),"")))))) -> 48000 | AI6: =IF(매핑v2!H6="○",P6,"") -> 7500 | AJ6: =IF(매핑v2!H6="○","○","X") -> ○ | AK6: =IF(매핑v2!H6="○",Y6,"") -> 0 | AL6: =IF(매핑v2!H6="○","○","X") -> ○ | AM6: =IF(매핑v2!H6="○",AH6,"") -> 48000 | AN6: =IF(매핑v2!H6="○","○","X") -> ○ | AO6: =IF(매핑v2!I6="○",P6,"") -> 7500 | AP6: =IF(매핑v2!I6="○","○","X") -> ○ | AQ6: =IF(매핑v2!I6="○",Y6,"") -> 0 | AR6: =IF(매핑v2!I6="○","○","X") -> ○ | AS6: =IF(매핑v2!I6="○",AH6,"") -> 48000 | AT6: =IF(매핑v2!I6="○","○","X") -> ○ | AU6: =IF(매핑v2!J6="○",P6,"") -> 7500 | AV6: =IF(매핑v2!J6="○","○","X") -> ○ | AW6: =IF(매핑v2!J6="○",Y6,"") -> 0 | AX6: =IF(매핑v2!J6="○","○","X") -> ○ | AY6: =IF(매핑v2!J6="○",AH6,"") -> 48000 | AZ6: =IF(매핑v2!J6="○","○","X") -> ○ | BA6: =IF(매핑v2!K6="○",P6,"") -> 7500 | BB6: =IF(매핑v2!K6="○","○","X") -> ○ | BC6: =IF(매핑v2!K6="○",Y6,"") -> 0 | BD6: =IF(매핑v2!K6="○","○","X") -> ○ | BE6: =IF(매핑v2!K6="○",AH6,"") -> 48000 | BF6: =IF(매핑v2!K6="○","○","X") -> ○ | BG6: =IF(매핑v2!L6="○",P6,"") -> 7500 | BH6: =IF(매핑v2!L6="○","○","X") -> ○ | BI6: =IF(매핑v2!L6="○",Y6,"") -> 0 | BJ6: ○ | BK6: X | BL6: ○ | BM6: ○ | BN6: ○ | BO6: X
A7: 6 | B7: 주거 | C7: 가습기 | D7: right spec | E7: 샤오미 저가형으로 충분 | F7: 복합식/과보조 기능 가습기 감가 상납 | G7: 수동 세척 힘든 구조 매일 닦느라 고생 | H7: 1 | I7: 37500 | J7: 5 | P7: =IF($H7=1,IF(AND(I7<>"",J7<>""),I7/J7/12,""),IF($H7=2,IF(AND(K7<>"",L7<>"",M7<>""),K7*L7*M7,""),IF($H7=3,IF(AND(N7<>"",O7<>""),N7/O7/12,""),IF($H7=4,IF(AND(I7<>"",J7<>""),I7/J7/12,0)+IF(AND(K7<>"",L7<>"",M7<>""),K7*L7*M7,0),IF($H7=5,IF(AND(I7<>"",J7<>""),I7/J7/12,0)+IF(AND(N7<>"",O7<>""),N7/O7/12,0),IF($H7=6,IF(AND(K7<>"",L7<>"",M7<>""),K7*L7*M7,0)+IF(AND(N7<>"",O7<>""),N7/O7/12,0),"")))))) -> 625 | Q7: 1 | R7: 600000 | S7: 5 | Y7: =IF($Q7=1,IF(AND(R7<>"",S7<>""),R7/S7/12,""),IF($Q7=2,IF(AND(T7<>"",U7<>"",V7<>""),T7*U7*V7,""),IF($Q7=3,IF(AND(W7<>"",X7<>""),W7/X7/12,""),IF($Q7=4,IF(AND(R7<>"",S7<>""),R7/S7/12,0)+IF(AND(T7<>"",U7<>"",V7<>""),T7*U7*V7,0),IF($Q7=5,IF(AND(R7<>"",S7<>""),R7/S7/12,0)+IF(AND(W7<>"",X7<>""),W7/X7/12,0),IF($Q7=6,IF(AND(T7<>"",U7<>"",V7<>""),T7*U7*V7,0)+IF(AND(W7<>"",X7<>""),W7/X7/12,0),"")))))) -> 10000 | Z7: 1 | AA7: 120000 | AB7: 5 | AH7: =IF($Z7=1,IF(AND(AA7<>"",AB7<>""),AA7/AB7/12,""),IF($Z7=2,IF(AND(AC7<>"",AD7<>"",AE7<>""),AC7*AD7*AE7,""),IF($Z7=3,IF(AND(AF7<>"",AG7<>""),AF7/AG7/12,""),IF($Z7=4,IF(AND(AA7<>"",AB7<>""),AA7/AB7/12,0)+IF(AND(AC7<>"",AD7<>"",AE7<>""),AC7*AD7*AE7,0),IF($Z7=5,IF(AND(AA7<>"",AB7<>""),AA7/AB7/12,0)+IF(AND(AF7<>"",AG7<>""),AF7/AG7/12,0),IF($Z7=6,IF(AND(AC7<>"",AD7<>"",AE7<>""),AC7*AD7*AE7,0)+IF(AND(AF7<>"",AG7<>""),AF7/AG7/12,0),"")))))) -> 2000 | AI7: =IF(매핑v2!H7="○",P7,"") -> 625 | AJ7: =IF(매핑v2!H7="○","○","X") -> ○ | AK7: =IF(매핑v2!H7="○",Y7,"") -> 10000 | AL7: =IF(매핑v2!H7="○","○","X") -> ○ | AM7: =IF(매핑v2!H7="○",AH7,"") -> 2000 | AN7: =IF(매핑v2!H7="○","○","X") -> ○ | AO7: =IF(매핑v2!I7="○",P7,"") -> 625 | AP7: =IF(매핑v2!I7="○","○","X") -> ○ | AQ7: =IF(매핑v2!I7="○",Y7,"") -> 10000 | AR7: =IF(매핑v2!I7="○","○","X") -> ○ | AS7: =IF(매핑v2!I7="○",AH7,"") -> 2000 | AT7: =IF(매핑v2!I7="○","○","X") -> ○ | AU7: =IF(매핑v2!J7="○",P7,"") -> 625 | AV7: =IF(매핑v2!J7="○","○","X") -> ○ | AW7: =IF(매핑v2!J7="○",Y7,"") -> 10000 | AX7: =IF(매핑v2!J7="○","○","X") -> ○ | AY7: =IF(매핑v2!J7="○",AH7,"") -> 2000 | AZ7: =IF(매핑v2!J7="○","○","X") -> ○ | BA7: =IF(매핑v2!K7="○",P7,"") -> 625 | BB7: =IF(매핑v2!K7="○","○","X") -> ○ | BC7: =IF(매핑v2!K7="○",Y7,"") -> 10000 | BD7: =IF(매핑v2!K7="○","○","X") -> ○ | BE7: =IF(매핑v2!K7="○",AH7,"") -> 2000 | BF7: =IF(매핑v2!K7="○","○","X") -> ○ | BG7: =IF(매핑v2!L7="○",P7,"") -> 625 | BH7: =IF(매핑v2!L7="○","○","X") -> ○ | BI7: =IF(매핑v2!L7="○",Y7,"") -> 10000 | BJ7: ○ | BK7: X | BL7: ○ | BM7: ○ | BN7: X | BO7: X
A8: 7 | B8: 주거 | C8: 조명 | D8: DIY | E8: LED 전구 + 한지로 직접 제작 | F8: 수입/디자이너 조명 구매 감가 | G8: 인테리어 포기 (수면 조명 없음) | H8: 1 | I8: 10000 | J8: 5 | P8: =IF($H8=1,IF(AND(I8<>"",J8<>""),I8/J8/12,""),IF($H8=2,IF(AND(K8<>"",L8<>"",M8<>""),K8*L8*M8,""),IF($H8=3,IF(AND(N8<>"",O8<>""),N8/O8/12,""),IF($H8=4,IF(AND(I8<>"",J8<>""),I8/J8/12,0)+IF(AND(K8<>"",L8<>"",M8<>""),K8*L8*M8,0),IF($H8=5,IF(AND(I8<>"",J8<>""),I8/J8/12,0)+IF(AND(N8<>"",O8<>""),N8/O8/12,0),IF($H8=6,IF(AND(K8<>"",L8<>"",M8<>""),K8*L8*M8,0)+IF(AND(N8<>"",O8<>""),N8/O8/12,0),"")))))) -> 166.66667 | Q8: 1 | R8: 250000 | S8: 5 | Y8: =IF($Q8=1,IF(AND(R8<>"",S8<>""),R8/S8/12,""),IF($Q8=2,IF(AND(T8<>"",U8<>"",V8<>""),T8*U8*V8,""),IF($Q8=3,IF(AND(W8<>"",X8<>""),W8/X8/12,""),IF($Q8=4,IF(AND(R8<>"",S8<>""),R8/S8/12,0)+IF(AND(T8<>"",U8<>"",V8<>""),T8*U8*V8,0),IF($Q8=5,IF(AND(R8<>"",S8<>""),R8/S8/12,0)+IF(AND(W8<>"",X8<>""),W8/X8/12,0),IF($Q8=6,IF(AND(T8<>"",U8<>"",V8<>""),T8*U8*V8,0)+IF(AND(W8<>"",X8<>""),W8/X8/12,0),"")))))) -> 4166.6667 | Z8: 1 | AH8: =IF($Z8=1,IF(AND(AA8<>"",AB8<>""),AA8/AB8/12,""),IF($Z8=2,IF(AND(AC8<>"",AD8<>"",AE8<>""),AC8*AD8*AE8,""),IF($Z8=3,IF(AND(AF8<>"",AG8<>""),AF8/AG8/12,""),IF($Z8=4,IF(AND(AA8<>"",AB8<>""),AA8/AB8/12,0)+IF(AND(AC8<>"",AD8<>"",AE8<>""),AC8*AD8*AE8,0),IF($Z8=5,IF(AND(AA8<>"",AB8<>""),AA8/AB8/12,0)+IF(AND(AF8<>"",AG8<>""),AF8/AG8/12,0),IF($Z8=6,IF(AND(AC8<>"",AD8<>"",AE8<>""),AC8*AD8*AE8,0)+IF(AND(AF8<>"",AG8<>""),AF8/AG8/12,0),"")))))) | AI8: =IF(매핑v2!H8="○",P8,"") -> 166.66667 | AJ8: =IF(매핑v2!H8="○","○","X") -> ○ | AK8: =IF(매핑v2!H8="○",Y8,"") -> 4166.6667 | AL8: =IF(매핑v2!H8="○","○","X") -> ○ | AM8: =IF(매핑v2!H8="○",AH8,"") | AN8: =IF(매핑v2!H8="○","○","X") -> ○ | AO8: =IF(매핑v2!I8="○",P8,"") -> 166.66667 | AP8: =IF(매핑v2!I8="○","○","X") -> ○ | AQ8: =IF(매핑v2!I8="○",Y8,"") -> 4166.6667 | AR8: =IF(매핑v2!I8="○","○","X") -> ○ | AS8: =IF(매핑v2!I8="○",AH8,"") | AT8: =IF(매핑v2!I8="○","○","X") -> ○ | AU8: =IF(매핑v2!J8="○",P8,"") -> 166.66667 | AV8: =IF(매핑v2!J8="○","○","X") -> ○ | AW8: =IF(매핑v2!J8="○",Y8,"") -> 4166.6667 | AX8: =IF(매핑v2!J8="○","○","X") -> ○ | AY8: =IF(매핑v2!J8="○",AH8,"") | AZ8: =IF(매핑v2!J8="○","○","X") -> ○ | BA8: =IF(매핑v2!K8="○",P8,"") -> 166.66667 | BB8: =IF(매핑v2!K8="○","○","X") -> ○ | BC8: =IF(매핑v2!K8="○",Y8,"") -> 4166.6667 | BD8: =IF(매핑v2!K8="○","○","X") -> ○ | BE8: =IF(매핑v2!K8="○",AH8,"") | BF8: =IF(매핑v2!K8="○","○","X") -> ○ | BG8: =IF(매핑v2!L8="○",P8,"") -> 166.66667 | BH8: =IF(매핑v2!L8="○","○","X") -> ○ | BI8: =IF(매핑v2!L8="○",Y8,"") -> 4166.6667 | BJ8: ○ | BK8: X | BL8: ○ | BM8: ○ | BN8: ○ | BO8: X
A9: 8 | B9: 주거 | C9: 유지보수 (힌지·문고리) | D9: 유지보수 | E9: 전기드릴 등 공구 구비 후 셀프 교체 | F9: 시공업체 출장비 및 마진 연환산 | G9: 손으로 교체하다 주말 하루 통째로 반납하여 시공 노동 | H9: 5 | I9: 150000 | J9: 8 | N9: 10000 | O9: 3 | P9: =IF($H9=1,IF(AND(I9<>"",J9<>""),I9/J9/12,""),IF($H9=2,IF(AND(K9<>"",L9<>"",M9<>""),K9*L9*M9,""),IF($H9=3,IF(AND(N9<>"",O9<>""),N9/O9/12,""),IF($H9=4,IF(AND(I9<>"",J9<>""),I9/J9/12,0)+IF(AND(K9<>"",L9<>"",M9<>""),K9*L9*M9,0),IF($H9=5,IF(AND(I9<>"",J9<>""),I9/J9/12,0)+IF(AND(N9<>"",O9<>""),N9/O9/12,0),IF($H9=6,IF(AND(K9<>"",L9<>"",M9<>""),K9*L9*M9,0)+IF(AND(N9<>"",O9<>""),N9/O9/12,0),"")))))) -> 1840.2778 | Q9: 1 | R9: 200000 | S9: 2 | Y9: =IF($Q9=1,IF(AND(R9<>"",S9<>""),R9/S9/12,""),IF($Q9=2,IF(AND(T9<>"",U9<>"",V9<>""),T9*U9*V9,""),IF($Q9=3,IF(AND(W9<>"",X9<>""),W9/X9/12,""),IF($Q9=4,IF(AND(R9<>"",S9<>""),R9/S9/12,0)+IF(AND(T9<>"",U9<>"",V9<>""),T9*U9*V9,0),IF($Q9=5,IF(AND(R9<>"",S9<>""),R9/S9/12,0)+IF(AND(W9<>"",X9<>""),W9/X9/12,0),IF($Q9=6,IF(AND(T9<>"",U9<>"",V9<>""),T9*U9*V9,0)+IF(AND(W9<>"",X9<>""),W9/X9/12,0),"")))))) -> 8333.3333 | Z9: 3 | AF9: 10000 | AG9: 3 | AH9: =IF($Z9=1,IF(AND(AA9<>"",AB9<>""),AA9/AB9/12,""),IF($Z9=2,IF(AND(AC9<>"",AD9<>"",AE9<>""),AC9*AD9*AE9,""),IF($Z9=3,IF(AND(AF9<>"",AG9<>""),AF9/AG9/12,""),IF($Z9=4,IF(AND(AA9<>"",AB9<>""),AA9/AB9/12,0)+IF(AND(AC9<>"",AD9<>"",AE9<>""),AC9*AD9*AE9,0),IF($Z9=5,IF(AND(AA9<>"",AB9<>""),AA9/AB9/12,0)+IF(AND(AF9<>"",AG9<>""),AF9/AG9/12,0),IF($Z9=6,IF(AND(AC9<>"",AD9<>"",AE9<>""),AC9*AD9*AE9,0)+IF(AND(AF9<>"",AG9<>""),AF9/AG9/12,0),"")))))) -> 277.77778 | AI9: =IF(매핑v2!H9="○",P9,"") -> 1840.2778 | AJ9: =IF(매핑v2!H9="○","○","X") -> ○ | AK9: =IF(매핑v2!H9="○",Y9,"") -> 8333.3333 | AL9: =IF(매핑v2!H9="○","○","X") -> ○ | AM9: =IF(매핑v2!H9="○",AH9,"") -> 277.77778 | AN9: =IF(매핑v2!H9="○","○","X") -> ○ | AO9: =IF(매핑v2!I9="○",P9,"") -> 1840.2778 | AP9: =IF(매핑v2!I9="○","○","X") -> ○ | AQ9: =IF(매핑v2!I9="○",Y9,"") -> 8333.3333 | AR9: =IF(매핑v2!I9="○","○","X") -> ○ | AS9: =IF(매핑v2!I9="○",AH9,"") -> 277.77778 | AT9: =IF(매핑v2!I9="○","○","X") -> ○ | AU9: =IF(매핑v2!J9="○",P9,"") -> 1840.2778 | AV9: =IF(매핑v2!J9="○","○","X") -> ○ | AW9: =IF(매핑v2!J9="○",Y9,"") -> 8333.3333 | AX9: =IF(매핑v2!J9="○","○","X") -> ○ | AY9: =IF(매핑v2!J9="○",AH9,"") -> 277.77778 | AZ9: =IF(매핑v2!J9="○","○","X") -> ○ | BA9: =IF(매핑v2!K9="○",P9,"") -> 1840.2778 | BB9: =IF(매핑v2!K9="○","○","X") -> ○ | BC9: =IF(매핑v2!K9="○",Y9,"") -> 8333.3333 | BD9: =IF(매핑v2!K9="○","○","X") -> ○ | BE9: =IF(매핑v2!K9="○",AH9,"") -> 277.77778 | BF9: =IF(매핑v2!K9="○","○","X") -> ○ | BG9: =IF(매핑v2!L9="○",P9,"") -> 1840.2778 | BH9: =IF(매핑v2!L9="○","○","X") -> ○ | BI9: =IF(매핑v2!L9="○",Y9,"") -> 8333.3333 | BJ9: ○ | BK9: X | BL9: ○ | BM9: ○ | BN9: ○ | BO9: X
A10: 9 | B10: 주거 | C10: 비데 필터 | D10: 부품 교환 | E10: 필터 직구 후 직접 교체 | F10: 브랜드 렌탈 케어 서비스 상납 | G10: 호환 필터 구입하고, 고전하며 포기, 비데 수명 단축 | H10: 5 | I10: 160000 | J10: 5 | N10: 6000 | O10: 0.5 | P10: =IF($H10=1,IF(AND(I10<>"",J10<>""),I10/J10/12,""),IF($H10=2,IF(AND(K10<>"",L10<>"",M10<>""),K10*L10*M10,""),IF($H10=3,IF(AND(N10<>"",O10<>""),N10/O10/12,""),IF($H10=4,IF(AND(I10<>"",J10<>""),I10/J10/12,0)+IF(AND(K10<>"",L10<>"",M10<>""),K10*L10*M10,0),IF($H10=5,IF(AND(I10<>"",J10<>""),I10/J10/12,0)+IF(AND(N10<>"",O10<>""),N10/O10/12,0),IF($H10=6,IF(AND(K10<>"",L10<>"",M10<>""),K10*L10*M10,0)+IF(AND(N10<>"",O10<>""),N10/O10/12,0),"")))))) -> 3666.6667 | Q10: 5 | T10: 1 | U10: 1 | V10: 30000 | Y10: =IF($Q10=1,IF(AND(R10<>"",S10<>""),R10/S10/12,""),IF($Q10=2,IF(AND(T10<>"",U10<>"",V10<>""),T10*U10*V10,""),IF($Q10=3,IF(AND(W10<>"",X10<>""),W10/X10/12,""),IF($Q10=4,IF(AND(R10<>"",S10<>""),R10/S10/12,0)+IF(AND(T10<>"",U10<>"",V10<>""),T10*U10*V10,0),IF($Q10=5,IF(AND(R10<>"",S10<>""),R10/S10/12,0)+IF(AND(W10<>"",X10<>""),W10/X10/12,0),IF($Q10=6,IF(AND(T10<>"",U10<>"",V10<>""),T10*U10*V10,0)+IF(AND(W10<>"",X10<>""),W10/X10/12,0),"")))))) -> 0 | Z10: 5 | AA10: 160000 | AB10: 2 | AF10: 6000 | AG10: 0.25 | AH10: =IF($Z10=1,IF(AND(AA10<>"",AB10<>""),AA10/AB10/12,""),IF($Z10=2,IF(AND(AC10<>"",AD10<>"",AE10<>""),AC10*AD10*AE10,""),IF($Z10=3,IF(AND(AF10<>"",AG10<>""),AF10/AG10/12,""),IF($Z10=4,IF(AND(AA10<>"",AB10<>""),AA10/AB10/12,0)+IF(AND(AC10<>"",AD10<>"",AE10<>""),AC10*AD10*AE10,0),IF($Z10=5,IF(AND(AA10<>"",AB10<>""),AA10/AB10/12,0)+IF(AND(AF10<>"",AG10<>""),AF10/AG10/12,0),IF($Z10=6,IF(AND(AC10<>"",AD10<>"",AE10<>""),AC10*AD10*AE10,0)+IF(AND(AF10<>"",AG10<>""),AF10/AG10/12,0),"")))))) -> 8666.6667 | AI10: =IF(매핑v2!H10="○",P10,"") -> 3666.6667 | AJ10: =IF(매핑v2!H10="○","○","X") -> ○ | AK10: =IF(매핑v2!H10="○",Y10,"") -> 0 | AL10: =IF(매핑v2!H10="○","○","X") -> ○ | AM10: =IF(매핑v2!H10="○",AH10,"") -> 8666.6667 | AN10: =IF(매핑v2!H10="○","○","X") -> ○ | AO10: =IF(매핑v2!I10="○",P10,"") -> 3666.6667 | AP10: =IF(매핑v2!I10="○","○","X") -> ○ | AQ10: =IF(매핑v2!I10="○",Y10,"") -> 0 | AR10: =IF(매핑v2!I10="○","○","X") -> ○ | AS10: =IF(매핑v2!I10="○",AH10,"") -> 8666.6667 | AT10: =IF(매핑v2!I10="○","○","X") -> ○ | AU10: =IF(매핑v2!J10="○",P10,"") -> 3666.6667 | AV10: =IF(매핑v2!J10="○","○","X") -> ○ | AW10: =IF(매핑v2!J10="○",Y10,"") -> 0 | AX10: =IF(매핑v2!J10="○","○","X") -> ○ | AY10: =IF(매핑v2!J10="○",AH10,"") -> 8666.6667 | AZ10: =IF(매핑v2!J10="○","○","X") -> ○ | BA10: =IF(매핑v2!K10="○",P10,"") -> 3666.6667 | BB10: =IF(매핑v2!K10="○","○","X") -> ○ | BC10: =IF(매핑v2!K10="○",Y10,"") -> 0 | BD10: =IF(매핑v2!K10="○","○","X") -> ○ | BE10: =IF(매핑v2!K10="○",AH10,"") -> 8666.6667 | BF10: =IF(매핑v2!K10="○","○","X") -> ○ | BG10: =IF(매핑v2!L10="○",P10,"") -> 3666.6667 | BH10: =IF(매핑v2!L10="○","○","X") -> ○ | BI10: =IF(매핑v2!L10="○",Y10,"") -> 0 | BJ10: ○ | BK10: X | BL10: ○ | BM10: ○ | BN10: ○ | BO10: X
